Workbook

Sheet 27-ABRIL-2026
B1: REPORTE HORA A HORA MEDIDOR DE TANQUE ELEVADO
B3: DIA | C3: 46139
A4: 0 | B4: Hora | C4: LECTURA | D4: CONSOLIDADO (M3) | E4: consumo acumulado dia
B5: 1 | C5: 0 | D5: 0 | E5: =+D5 -> 0
B6: 2 | C6: 0 | D6: =SUM(C6-C5)*10 -> 0 | E6: =+D6+E5 -> 0
B7: 3 | C7: 0 | D7: =SUM(C7-C6)*10 -> 0 | E7: =+D7+E6 -> 0
B8: 4 | C8: 0 | D8: =SUM(C8-C7)*10 -> 0 | E8: =+D8+E7 -> 0
A9: 0 | B9: 5 | C9: 0 | D9: =SUM(C9-C8)*10 -> 0 | E9: =+D9+E8 -> 0
B10: 6 | C10: 0 | D10: =SUM(C10-C9)*10 -> 0 | E10: =+D10+E9 -> 0
B11: 7 | C11: 0 | D11: =SUM(C11-C10)*10 -> 0 | E11: =+D11+E10 -> 0
A12: 0 | B12: 8 | C12: 0 | D12: =SUM(C12-C11)*10 -> 0 | E12: =+D12+E11 -> 0
B13: 9 | C13: 0 | D13: =SUM(C13-C12)*10 -> 0 | E13: =+D13+E12 -> 0
B14: 10 | C14: 0 | D14: =SUM(C14-C13)*10 -> 0 | E14: =+D14+E13 -> 0
B15: 11 | C15: 0 | D15: =SUM(C15-C14)*10 -> 0 | E15: =+D15+E14 -> 0
A16: 0 | B16: 12 | C16: 0 | D16: =SUM(C16-C15)*10 -> 0 | E16: =+D16+E15 -> 0
B17: 13 | C17: 0 | D17: =SUM(C17-C16)*10 -> 0 | E17: =+D17+E16 -> 0
B18: 14 | C18: 11 | D18: 0 | E18: =+D18+E17 -> 0
B19: 15 | C19: 14 | D19: =SUM(C19-C18)*10 -> 30 | E19: =+D19+E18 -> 30
A20: 0 | B20: 16 | C20: 17 | D20: =SUM(C20-C19)*10 -> 30 | E20: =+D20+E19 -> 60
B21: 17 | C21: 20 | D21: =SUM(C21-C20)*10 -> 30 | E21: =+D21+E20 -> 90
B22: 18 | C22: 23 | D22: =SUM(C22-C21)*10 -> 30 | E22: =+D22+E21 -> 120
B23: 19 | C23: 26 | D23: =SUM(C23-C22)*10 -> 30 | E23: =+D23+E22 -> 150
B24: 20 | C24: 29 | D24: =SUM(C24-C23)*10 -> 30 | E24: =+D24+E23 -> 180
B25: 21 | C25: 32 | D25: =SUM(C25-C24)*10 -> 30 | E25: =+D25+E24 -> 210
B26: 22 | C26: 35 | D26: =SUM(C26-C25)*10 -> 30 | E26: =+D26+E25 -> 240
B27: 23 | C27: 35 | D27: =SUM(C27-C26)*10 -> 0 | E27: =+D27+E26 -> 240
B28: 24 | C28: 35 | D28: =SUM(C28-C27)*10 -> 0 | E28: =+D28+E27 -> 240
B29: MAXIMO | C29: =MAX(C5:C28) -> 35 | D29: =MAX(D5:D28) -> 30 | E29: =MAX(E5:E28) -> 240
B30: MINIMO | C30: =MIN(C5:C28) -> 0 | D30: =MIN(D5:D28) -> 0 | E30: =MIN(E5:E28) -> 0
B31: PROMEDIO | C31: =AVERAGE(C5:C28) -> 11.541667 | D31: =AVERAGE(D5:D28) -> 10 | E31: =AVERAGE(E5:E28) -> 65
B32: TOTAL | C32: =SUM(C5:C28) -> 277 | D32: =SUM(D5:D28) -> 240 | E32: =SUM(E5:E28) -> 1560

Sheet 28-ABRIL-2026
B1: REPORTE HORA A HORA MEDIDOR DE TANQUE ELEVADO
B3: DIA | C3: 46140
A4: 0 | B4: Hora | C4: LECTURA | D4: CONSOLIDADO (M3) | E4: consumo acumulado dia
B5: 1 | C5: 35 | D5: =C5-'27-ABRIL-2026'!C28 -> 0 | E5: =+D5 -> 0
B6: 2 | C6: 35 | D6: =SUM(C6-C5)*10 -> 0 | E6: =+D6+E5 -> 0
B7: 3 | C7: 35 | D7: =SUM(C7-C6)*10 -> 0 | E7: =+D7+E6 -> 0
B8: 4 | C8: 35 | D8: =SUM(C8-C7)*10 -> 0 | E8: =+D8+E7 -> 0
A9: 0 | B9: 5 | C9: 37 | D9: =SUM(C9-C8)*10 -> 20 | E9: =+D9+E8 -> 20
B10: 6 | C10: 39 | D10: =SUM(C10-C9)*10 -> 20 | E10: =+D10+E9 -> 40
B11: 7 | C11: 41 | D11: =SUM(C11-C10)*10 -> 20 | E11: =+D11+E10 -> 60
A12: 0 | B12: 8 | C12: 44 | D12: =SUM(C12-C11)*10 -> 30 | E12: =+D12+E11 -> 90
B13: 9 | C13: 46 | D13: =SUM(C13-C12)*10 -> 20 | E13: =+D13+E12 -> 110
B14: 10 | C14: 48 | D14: =SUM(C14-C13)*10 -> 20 | E14: =+D14+E13 -> 130
B15: 11 | C15: 51 | D15: =SUM(C15-C14)*10 -> 30 | E15: =+D15+E14 -> 160
A16: 0 | B16: 12 | C16: 53 | D16: =SUM(C16-C15)*10 -> 20 | E16: =+D16+E15 -> 180
B17: 13 | C17: 55 | D17: =SUM(C17-C16)*10 -> 20 | E17: =+D17+E16 -> 200
B18: 14 | C18: 57 | D18: =SUM(C18-C17)*10 -> 20 | E18: =+D18+E17 -> 220
B19: 15 | C19: 59 | D19: =SUM(C19-C18)*10 -> 20 | E19: =+D19+E18 -> 240
A20: 0 | B20: 16 | C20: 61 | D20: =SUM(C20-C19)*10 -> 20 | E20: =+D20+E19 -> 260
B21: 17 | C21: 63 | D21: =SUM(C21-C20)*10 -> 20 | E21: =+D21+E20 -> 280
B22: 18 | C22: 65 | D22: =SUM(C22-C21)*10 -> 20 | E22: =+D22+E21 -> 300
B23: 19 | C23: 67 | D23: =SUM(C23-C22)*10 -> 20 | E23: =+D23+E22 -> 320
B24: 20 | C24: 69 | D24: =SUM(C24-C23)*10 -> 20 | E24: =+D24+E23 -> 340
B25: 21 | C25: 71 | D25: =SUM(C25-C24)*10 -> 20 | E25: =+D25+E24 -> 360
B26: 22 | C26: 73 | D26: =SUM(C26-C25)*10 -> 20 | E26: =+D26+E25 -> 380
B27: 23 | C27: 73 | D27: =SUM(C27-C26)*10 -> 0 | E27: =+D27+E26 -> 380
B28: 24 | C28: 73 | D28: =SUM(C28-C27)*10 -> 0 | E28: =+D28+E27 -> 380
B29: MAXIMO | C29: =MAX(C5:C28) -> 73 | D29: =MAX(D5:D28) -> 30 | E29: =MAX(E5:E28) -> 380
B30: MINIMO | C30: =MIN(C5:C28) -> 35 | D30: =MIN(D5:D28) -> 0 | E30: =MIN(E5:E28) -> 0
B31: PROMEDIO | C31: =AVERAGE(C5:C28) -> 53.541667 | D31: =AVERAGE(D5:D28) -> 15.833333 | E31: =AVERAGE(E5:E28) -> 185.41667
B32: TOTAL | C32: =SUM(C5:C28) -> 1285 | D32: =SUM(D5:D28) -> 380 | E32: =SUM(E5:E28) -> 4450

Sheet 29-ABRIL-2026
B1: REPORTE HORA A HORA MEDIDOR DE TANQUE ELEVADO
B3: DIA | C3: 46141
A4: 0 | B4: Hora | C4: LECTURA | D4: CONSOLIDADO (M3) | E4: consumo acumulado dia
B5: 1 | C5: 73 | D5: =C5-'28-ABRIL-2026'!C28 -> 0 | E5: =+D5 -> 0
B6: 2 | C6: 73 | D6: =SUM(C6-C5)*10 -> 0 | E6: =+D6+E5 -> 0
B7: 3 | C7: 73 | D7: =SUM(C7-C6)*10 -> 0 | E7: =+D7+E6 -> 0
B8: 4 | C8: 73 | D8: =SUM(C8-C7)*10 -> 0 | E8: =+D8+E7 -> 0
A9: 0 | B9: 5 | C9: 75 | D9: =SUM(C9-C8)*10 -> 20 | E9: =+D9+E8 -> 20
B10: 6 | C10: 79 | D10: =SUM(C10-C9)*10 -> 40 | E10: =+D10+E9 -> 60
B11: 7 | C11: 81 | D11: =SUM(C11-C10)*10 -> 20 | E11: =+D11+E10 -> 80
A12: 0 | B12: 8 | C12: 83 | D12: =SUM(C12-C11)*10 -> 20 | E12: =+D12+E11 -> 100
B13: 9 | C13: 85 | D13: =SUM(C13-C12)*10 -> 20 | E13: =+D13+E12 -> 120
B14: 10 | C14: 87 | D14: =SUM(C14-C13)*10 -> 20 | E14: =+D14+E13 -> 140
B15: 11 | C15: 89 | D15: =SUM(C15-C14)*10 -> 20 | E15: =+D15+E14 -> 160
A16: 0 | B16: 12 | C16: 91 | D16: =SUM(C16-C15)*10 -> 20 | E16: =+D16+E15 -> 180
B17: 13 | C17: 93 | D17: =SUM(C17-C16)*10 -> 20 | E17: =+D17+E16 -> 200
B18: 14 | C18: 96 | D18: =SUM(C18-C17)*10 -> 30 | E18: =+D18+E17 -> 230
B19: 15 | C19: 97 | D19: =SUM(C19-C18)*10 -> 10 | E19: =+D19+E18 -> 240
A20: 0 | B20: 16 | C20: 99 | D20: =SUM(C20-C19)*10 -> 20 | E20: =+D20+E19 -> 260
B21: 17 | C21: 100 | D21: =SUM(C21-C20)*10 -> 10 | E21: =+D21+E20 -> 270
B22: 18 | C22: 102 | D22: =SUM(C22-C21)*10 -> 20 | E22: =+D22+E21 -> 290
B23: 19 | C23: 104 | D23: =SUM(C23-C22)*10 -> 20 | E23: =+D23+E22 -> 310
B24: 20 | C24: 106 | D24: =SUM(C24-C23)*10 -> 20 | E24: =+D24+E23 -> 330
B25: 21 | C25: 109 | D25: =SUM(C25-C24)*10 -> 30 | E25: =+D25+E24 -> 360
B26: 22 | C26: 111 | D26: =SUM(C26-C25)*10 -> 20 | E26: =+D26+E25 -> 380
B27: 23 | C27: 111 | D27: =SUM(C27-C26)*10 -> 0 | E27: =+D27+E26 -> 380
B28: 24 | C28: 111 | D28: =SUM(C28-C27)*10 -> 0 | E28: =+D28+E27 -> 380
B29: MAXIMO | C29: =MAX(C5:C28) -> 111 | D29: =MAX(D5:D28) -> 40 | E29: =MAX(E5:E28) -> 380
B30: MINIMO | C30: =MIN(C5:C28) -> 73 | D30: =MIN(D5:D28) -> 0 | E30: =MIN(E5:E28) -> 0
B31: PROMEDIO | C31: =AVERAGE(C5:C28) -> 91.708333 | D31: =AVERAGE(D5:D28) -> 15.833333 | E31: =AVERAGE(E5:E28) -> 187.08333
B32: TOTAL | C32: =SUM(C5:C28) -> 2201 | D32: =SUM(D5:D28) -> 380 | E32: =SUM(E5:E28) -> 4490

Sheet 30-ABRIL-2026
B1: REPORTE HORA A HORA MEDIDOR DE TANQUE ELEVADO
B3: DIA | C3: 46142
A4: 0 | B4: Hora | C4: LECTURA | D4: CONSOLIDADO (M3) | E4: consumo acumulado dia
B5: 1 | C5: 111 | D5: =C5-'29-ABRIL-2026'!C28 -> 0 | E5: =+D5 -> 0
B6: 2 | C6: 111 | D6: =SUM(C6-C5)*10 -> 0 | E6: =+D6+E5 -> 0
B7: 3 | C7: 111 | D7: =SUM(C7-C6)*10 -> 0 | E7: =+D7+E6 -> 0
B8: 4 | C8: 111 | D8: =SUM(C8-C7)*10 -> 0 | E8: =+D8+E7 -> 0
A9: 0 | B9: 5 | C9: 114 | D9: =SUM(C9-C8)*10 -> 30 | E9: =+D9+E8 -> 30
B10: 6 | C10: 117 | D10: =SUM(C10-C9)*10 -> 30 | E10: =+D10+E9 -> 60
B11: 7 | C11: 119 | D11: =SUM(C11-C10)*10 -> 20 | E11: =+D11+E10 -> 80
A12: 0 | B12: 8 | C12: 121 | D12: =SUM(C12-C11)*10 -> 20 | E12: =+D12+E11 -> 100
B13: 9 | C13: 124 | D13: =SUM(C13-C12)*10 -> 30 | E13: =+D13+E12 -> 130
B14: 10 | C14: 125 | D14: =SUM(C14-C13)*10 -> 10 | E14: =+D14+E13 -> 140
B15: 11 | C15: 128 | D15: =SUM(C15-C14)*10 -> 30 | E15: =+D15+E14 -> 170
A16: 0 | B16: 12 | C16: 130 | D16: =SUM(C16-C15)*10 -> 20 | E16: =+D16+E15 -> 190
B17: 13 | C17: 132 | D17: =SUM(C17-C16)*10 -> 20 | E17: =+D17+E16 -> 210
B18: 14 | C18: 134 | D18: =SUM(C18-C17)*10 -> 20 | E18: =+D18+E17 -> 230
B19: 15 | C19: 136 | D19: =SUM(C19-C18)*10 -> 20 | E19: =+D19+E18 -> 250
A20: 0 | B20: 16 | C20: 138 | D20: =SUM(C20-C19)*10 -> 20 | E20: =+D20+E19 -> 270
B21: 17 | C21: 139 | D21: =SUM(C21-C20)*10 -> 10 | E21: =+D21+E20 -> 280
B22: 18 | C22: 141 | D22: =SUM(C22-C21)*10 -> 20 | E22: =+D22+E21 -> 300
B23: 19 | C23: 143 | D23: =SUM(C23-C22)*10 -> 20 | E23: =+D23+E22 -> 320
B24: 20 | C24: 145 | D24: =SUM(C24-C23)*10 -> 20 | E24: =+D24+E23 -> 340
B25: 21 | C25: 147 | D25: =SUM(C25-C24)*10 -> 20 | E25: =+D25+E24 -> 360
B26: 22 | C26: 149 | D26: =SUM(C26-C25)*10 -> 20 | E26: =+D26+E25 -> 380
B27: 23 | C27: 149 | D27: =SUM(C27-C26)*10 -> 0 | E27: =+D27+E26 -> 380
B28: 24 | C28: 149 | D28: =SUM(C28-C27)*10 -> 0 | E28: =+D28+E27 -> 380
B29: MAXIMO | C29: =MAX(C5:C28) -> 149 | D29: =MAX(D5:D28) -> 30 | E29: =MAX(E5:E28) -> 380
B30: MINIMO | C30: =MIN(C5:C28) -> 111 | D30: =MIN(D5:D28) -> 0 | E30: =MIN(E5:E28) -> 0
B31: PROMEDIO | C31: =AVERAGE(C5:C28) -> 130.16667 | D31: =AVERAGE(D5:D28) -> 15.833333 | E31: =AVERAGE(E5:E28) -> 191.66667
B32: TOTAL | C32: =SUM(C5:C28) -> 3124 | D32: =SUM(D5:D28) -> 380 | E32: =SUM(E5:E28) -> 4600

Sheet 1-MAYO-2026
B1: REPORTE HORA A HORA MEDIDOR DE TANQUE ELEVADO
B3: DIA | C3: 46143
A4: 0 | B4: Hora | C4: LECTURA | D4: CONSOLIDADO (M3) | E4: consumo acumulado dia
B5: 1 | C5: 149 | D5: =C5-'30-ABRIL-2026'!C28 -> 0 | E5: =+D5 -> 0
B6: 2 | C6: 149 | D6: =SUM(C6-C5)*10 -> 0 | E6: =+D6+E5 -> 0
B7: 3 | C7: 149 | D7: =SUM(C7-C6)*10 -> 0 | E7: =+D7+E6 -> 0
B8: 4 | C8: 149 | D8: =SUM(C8-C7)*10 -> 0 | E8: =+D8+E7 -> 0
A9: 0 | B9: 5 | C9: 153 | D9: =SUM(C9-C8)*10 -> 40 | E9: =+D9+E8 -> 40
B10: 6 | C10: 155 | D10: =SUM(C10-C9)*10 -> 20 | E10: =+D10+E9 -> 60
B11: 7 | C11: 157 | D11: =SUM(C11-C10)*10 -> 20 | E11: =+D11+E10 -> 80
A12: 0 | B12: 8 | C12: 159 | D12: =SUM(C12-C11)*10 -> 20 | E12: =+D12+E11 -> 100
B13: 9 | C13: 161 | D13: =SUM(C13-C12)*10 -> 20 | E13: =+D13+E12 -> 120
B14: 10 | C14: 164 | D14: =SUM(C14-C13)*10 -> 30 | E14: =+D14+E13 -> 150
B15: 11 | C15: 168 | D15: =SUM(C15-C14)*10 -> 40 | E15: =+D15+E14 -> 190
A16: 0 | B16: 12 | C16: 173 | D16: =SUM(C16-C15)*10 -> 50 | E16: =+D16+E15 -> 240
B17: 13 | C17: 177 | D17: =SUM(C17-C16)*10 -> 40 | E17: =+D17+E16 -> 280
B18: 14 | C18: 179 | D18: =SUM(C18-C17)*10 -> 20 | E18: =+D18+E17 -> 300
B19: 15 | C19: 182 | D19: =SUM(C19-C18)*10 -> 30 | E19: =+D19+E18 -> 330
A20: 0 | B20: 16 | C20: 185 | D20: =SUM(C20-C19)*10 -> 30 | E20: =+D20+E19 -> 360
B21: 17 | C21: 187 | D21: =SUM(C21-C20)*10 -> 20 | E21: =+D21+E20 -> 380
B22: 18 | C22: 189 | D22: =SUM(C22-C21)*10 -> 20 | E22: =+D22+E21 -> 400
B23: 19 | C23: 192 | D23: =SUM(C23-C22)*10 -> 30 | E23: =+D23+E22 -> 430
B24: 20 | C24: 195 | D24: =SUM(C24-C23)*10 -> 30 | E24: =+D24+E23 -> 460
B25: 21 | C25: 197 | D25: =SUM(C25-C24)*10 -> 20 | E25: =+D25+E24 -> 480
B26: 22 | C26: 199 | D26: =SUM(C26-C25)*10 -> 20 | E26: =+D26+E25 -> 500
B27: 23 | C27: 199 | D27: =SUM(C27-C26)*10 -> 0 | E27: =+D27+E26 -> 500
B28: 24 | C28: 199 | D28: =SUM(C28-C27)*10 -> 0 | E28: =+D28+E27 -> 500
B29: MAXIMO | C29: =MAX(C5:C28) -> 199 | D29: =MAX(D5:D28) -> 50 | E29: =MAX(E5:E28) -> 500
B30: MINIMO | C30: =MIN(C5:C28) -> 149 | D30: =MIN(D5:D28) -> 0 | E30: =MIN(E5:E28) -> 0
B31: PROMEDIO | C31: =AVERAGE(C5:C28) -> 173.58333 | D31: =AVERAGE(D5:D28) -> 20.833333 | E31: =AVERAGE(E5:E28) -> 245.83333
B32: TOTAL | C32: =SUM(C5:C28) -> 4166 | D32: =SUM(D5:D28) -> 500 | E32: =SUM(E5:E28) -> 5900

Sheet 2-MAYO-2026
B1: REPORTE HORA A HORA MEDIDOR DE TANQUE ELEVADO
B3: DIA | C3: 46143
A4: 0 | B4: Hora | C4: LECTURA | D4: CONSOLIDADO (M3) | E4: consumo acumulado dia
B5: 1 | C5: 199 | D5: =C5-'1-MAYO-2026'!C28 -> 0 | E5: =+D5 -> 0
B6: 2 | C6: 199 | D6: =SUM(C6-C5)*10 -> 0 | E6: =+D6+E5 -> 0
B7: 3 | C7: 199 | D7: =SUM(C7-C6)*10 -> 0 | E7: =+D7+E6 -> 0
B8: 4 | C8: 199 | D8: =SUM(C8-C7)*10 -> 0 | E8: =+D8+E7 -> 0
A9: 0 | B9: 5 | C9: 201 | D9: =SUM(C9-C8)*10 -> 20 | E9: =+D9+E8 -> 20
B10: 6 | C10: 203 | D10: =SUM(C10-C9)*10 -> 20 | E10: =+D10+E9 -> 40
B11: 7 | C11: 206 | D11: =SUM(C11-C10)*10 -> 30 | E11: =+D11+E10 -> 70
A12: 0 | B12: 8 | C12: 209 | D12: =SUM(C12-C11)*10 -> 30 | E12: =+D12+E11 -> 100
B13: 9 | C13: 213 | D13: =SUM(C13-C12)*10 -> 40 | E13: =+D13+E12 -> 140
B14: 10 | C14: 215 | D14: =SUM(C14-C13)*10 -> 20 | E14: =+D14+E13 -> 160
B15: 11 | C15: 217 | D15: =SUM(C15-C14)*10 -> 20 | E15: =+D15+E14 -> 180
A16: 0 | B16: 12 | C16: 219 | D16: =SUM(C16-C15)*10 -> 20 | E16: =+D16+E15 -> 200
B17: 13 | C17: 221 | D17: =SUM(C17-C16)*10 -> 20 | E17: =+D17+E16 -> 220
B18: 14 | C18: 224 | D18: =SUM(C18-C17)*10 -> 30 | E18: =+D18+E17 -> 250
B19: 15 | C19: 227 | D19: =SUM(C19-C18)*10 -> 30 | E19: =+D19+E18 -> 280
A20: 0 | B20: 16 | C20: 229 | D20: =SUM(C20-C19)*10 -> 20 | E20: =+D20+E19 -> 300
B21: 17 | C21: 231 | D21: =SUM(C21-C20)*10 -> 20 | E21: =+D21+E20 -> 320
B22: 18 | C22: 233 | D22: =SUM(C22-C21)*10 -> 20 | E22: =+D22+E21 -> 340
B23: 19 | C23: 234 | D23: =SUM(C23-C22)*10 -> 10 | E23: =+D23+E22 -> 350
B24: 20 | C24: 236 | D24: =SUM(C24-C23)*10 -> 20 | E24: =+D24+E23 -> 370
B25: 21 | C25: 238 | D25: =SUM(C25-C24)*10 -> 20 | E25: =+D25+E24 -> 390
B26: 22 | C26: 240 | D26: =SUM(C26-C25)*10 -> 20 | E26: =+D26+E25 -> 410
B27: 23 | C27: 240 | D27: =SUM(C27-C26)*10 -> 0 | E27: =+D27+E26 -> 410
B28: 24 | C28: 240 | D28: =SUM(C28-C27)*10 -> 0 | E28: =+D28+E27 -> 410
B29: MAXIMO | C29: =MAX(C5:C28) -> 240 | D29: =MAX(D5:D28) -> 40 | E29: =MAX(E5:E28) -> 410
B30: MINIMO | C30: =MIN(C5:C28) -> 199 | D30: =MIN(D5:D28) -> 0 | E30: =MIN(E5:E28) -> 0
B31: PROMEDIO | C31: =AVERAGE(C5:C28) -> 219.66667 | D31: =AVERAGE(D5:D28) -> 17.083333 | E31: =AVERAGE(E5:E28) -> 206.66667
B32: TOTAL | C32: =SUM(C5:C28) -> 5272 | D32: =SUM(D5:D28) -> 410 | E32: =SUM(E5:E28) -> 4960

Sheet 3-MAYO-2026 
B1: REPORTE HORA A HORA MEDIDOR DE TANQUE ELEVADO
B3: DIA | C3: 46145
A4: 0 | B4: Hora | C4: LECTURA | D4: CONSOLIDADO (M3) | E4: consumo acumulado dia
B5: 1 | C5: 240 | D5: =C5-'2-MAYO-2026'!C28 -> 0 | E5: =+D5 -> 0
B6: 2 | C6: 240 | D6: =SUM(C6-C5)*10 -> 0 | E6: =+D6+E5 -> 0
B7: 3 | C7: 240 | D7: =SUM(C7-C6)*10 -> 0 | E7: =+D7+E6 -> 0
B8: 4 | C8: 240 | D8: =SUM(C8-C7)*10 -> 0 | E8: =+D8+E7 -> 0
A9: 0 | B9: 5 | C9: 242 | D9: =SUM(C9-C8)*10 -> 20 | E9: =+D9+E8 -> 20
B10: 6 | C10: 244 | D10: =SUM(C10-C9)*10 -> 20 | E10: =+D10+E9 -> 40
B11: 7 | C11: 246 | D11: =SUM(C11-C10)*10 -> 20 | E11: =+D11+E10 -> 60
A12: 0 | B12: 8 | C12: 248 | D12: =SUM(C12-C11)*10 -> 20 | E12: =+D12+E11 -> 80
B13: 9 | C13: 252 | D13: =SUM(C13-C12)*10 -> 40 | E13: =+D13+E12 -> 120
B14: 10 | C14: 257 | D14: =SUM(C14-C13)*10 -> 50 | E14: =+D14+E13 -> 170
B15: 11 | C15: 262 | D15: =SUM(C15-C14)*10 -> 50 | E15: =+D15+E14 -> 220
A16: 0 | B16: 12 | C16: 267 | D16: =SUM(C16-C15)*10 -> 50 | E16: =+D16+E15 -> 270
B17: 13 | C17: 270 | D17: =SUM(C17-C16)*10 -> 30 | E17: =+D17+E16 -> 300
B18: 14 | C18: 272 | D18: =SUM(C18-C17)*10 -> 20 | E18: =+D18+E17 -> 320
B19: 15 | C19: 274 | D19: =SUM(C19-C18)*10 -> 20 | E19: =+D19+E18 -> 340
A20: 0 | B20: 16 | C20: 276 | D20: =SUM(C20-C19)*10 -> 20 | E20: =+D20+E19 -> 360
B21: 17 | C21: 278 | D21: =SUM(C21-C20)*10 -> 20 | E21: =+D21+E20 -> 380
B22: 18 | C22: 280 | D22: =SUM(C22-C21)*10 -> 20 | E22: =+D22+E21 -> 400
B23: 19 | C23: 282 | D23: =SUM(C23-C22)*10 -> 20 | E23: =+D23+E22 -> 420
B24: 20 | C24: 284 | D24: =SUM(C24-C23)*10 -> 20 | E24: =+D24+E23 -> 440
B25: 21 | C25: 286 | D25: =SUM(C25-C24)*10 -> 20 | E25: =+D25+E24 -> 460
B26: 22 | C26: 288 | D26: =SUM(C26-C25)*10 -> 20 | E26: =+D26+E25 -> 480
B27: 23 | C27: 288 | D27: =SUM(C27-C26)*10 -> 0 | E27: =+D27+E26 -> 480
B28: 24 | C28: 288 | D28: =SUM(C28-C27)*10 -> 0 | E28: =+D28+E27 -> 480
B29: MAXIMO | C29: =MAX(C5:C28) -> 288 | D29: =MAX(D5:D28) -> 50 | E29: =MAX(E5:E28) -> 480
B30: MINIMO | C30: =MIN(C5:C28) -> 240 | D30: =MIN(D5:D28) -> 0 | E30: =MIN(E5:E28) -> 0
B31: PROMEDIO | C31: =AVERAGE(C5:C28) -> 264.33333 | D31: =AVERAGE(D5:D28) -> 20 | E31: =AVERAGE(E5:E28) -> 243.33333
B32: TOTAL | C32: =SUM(C5:C28) -> 6344 | D32: =SUM(D5:D28) -> 480 | E32: =SUM(E5:E28) -> 5840

Sheet 4-MAYO-2026  
B1: REPORTE HORA A HORA MEDIDOR DE TANQUE ELEVADO
B3: DIA | C3: 46146
A4: 0 | B4: Hora | C4: LECTURA | D4: CONSOLIDADO (M3) | E4: consumo acumulado dia
B5: 1 | C5: 288 | D5: =C5-'3-MAYO-2026 '!C28 -> 0 | E5: =+D5 -> 0
B6: 2 | C6: 288 | D6: =SUM(C6-C5)*10 -> 0 | E6: =+D6+E5 -> 0
B7: 3 | C7: 288 | D7: =SUM(C7-C6)*10 -> 0 | E7: =+D7+E6 -> 0
B8: 4 | C8: 288 | D8: =SUM(C8-C7)*10 -> 0 | E8: =+D8+E7 -> 0
A9: 0 | B9: 5 | C9: 291 | D9: =SUM(C9-C8)*10 -> 30 | E9: =+D9+E8 -> 30
B10: 6 | C10: 293 | D10: =SUM(C10-C9)*10 -> 20 | E10: =+D10+E9 -> 50
B11: 7 | C11: 297 | D11: =SUM(C11-C10)*10 -> 40 | E11: =+D11+E10 -> 90
A12: 0 | B12: 8 | C12: 299 | D12: =SUM(C12-C11)*10 -> 20 | E12: =+D12+E11 -> 110
B13: 9 | C13: 301 | D13: =SUM(C13-C12)*10 -> 20 | E13: =+D13+E12 -> 130
B14: 10 | C14: 304 | D14: =SUM(C14-C13)*10 -> 30 | E14: =+D14+E13 -> 160
B15: 11 | C15: 306 | D15: =SUM(C15-C14)*10 -> 20 | E15: =+D15+E14 -> 180
A16: 0 | B16: 12 | C16: 308 | D16: =SUM(C16-C15)*10 -> 20 | E16: =+D16+E15 -> 200
B17: 13 | C17: 310 | D17: =SUM(C17-C16)*10 -> 20 | E17: =+D17+E16 -> 220
B18: 14 | C18: 312 | D18: =SUM(C18-C17)*10 -> 20 | E18: =+D18+E17 -> 240
B19: 15 | C19: 314 | D19: =SUM(C19-C18)*10 -> 20 | E19: =+D19+E18 -> 260
A20: 0 | B20: 16 | C20: 316 | D20: =SUM(C20-C19)*10 -> 20 | E20: =+D20+E19 -> 280
B21: 17 | C21: 317 | D21: =SUM(C21-C20)*10 -> 10 | E21: =+D21+E20 -> 290
B22: 18 | C22: 319 | D22: =SUM(C22-C21)*10 -> 20 | E22: =+D22+E21 -> 310
B23: 19 | C23: 321 | D23: =SUM(C23-C22)*10 -> 20 | E23: =+D23+E22 -> 330
B24: 20 | C24: 323 | D24: =SUM(C24-C23)*10 -> 20 | E24: =+D24+E23 -> 350
B25: 21 | C25: 325 | D25: =SUM(C25-C24)*10 -> 20 | E25: =+D25+E24 -> 370
B26: 22 | C26: 327 | D26: =SUM(C26-C25)*10 -> 20 | E26: =+D26+E25 -> 390
B27: 23 | C27: 327 | D27: =SUM(C27-C26)*10 -> 0 | E27: =+D27+E26 -> 390
B28: 24 | C28: 327 | D28: =SUM(C28-C27)*10 -> 0 | E28: =+D28+E27 -> 390
B29: MAXIMO | C29: =MAX(C5:C28) -> 327 | D29: =MAX(D5:D28) -> 40 | E29: =MAX(E5:E28) -> 390
B30: MINIMO | C30: =MIN(C5:C28) -> 288 | D30: =MIN(D5:D28) -> 0 | E30: =MIN(E5:E28) -> 0
B31: PROMEDIO | C31: =AVERAGE(C5:C28) -> 307.875 | D31: =AVERAGE(D5:D28) -> 16.25 | E31: =AVERAGE(E5:E28) -> 198.75
B32: TOTAL | C32: =SUM(C5:C28) -> 7389 | D32: =SUM(D5:D28) -> 390 | E32: =SUM(E5:E28) -> 4770

Sheet 5-MAYO-2026  
B1: REPORTE HORA A HORA MEDIDOR DE TANQUE ELEVADO
B3: DIA | C3: 46146
A4: 0 | B4: Hora | C4: LECTURA | D4: CONSOLIDADO (M3) | E4: consumo acumulado dia
B5: 1 | C5: 327 | D5: =C5-'4-MAYO-2026 '!C28 -> 0 | E5: =+D5 -> 0
B6: 2 | C6: 327 | D6: =SUM(C6-C5)*10 -> 0 | E6: =+D6+E5 -> 0
B7: 3 | C7: 327 | D7: =SUM(C7-C6)*10 -> 0 | E7: =+D7+E6 -> 0
B8: 4 | C8: 327 | D8: =SUM(C8-C7)*10 -> 0 | E8: =+D8+E7 -> 0
A9: 0 | B9: 5 | C9: 327 | D9: =SUM(C9-C8)*10 -> 0 | E9: =+D9+E8 -> 0
B10: 6 | C10: 333 | D10: =SUM(C10-C9)*10 -> 60 | E10: =+D10+E9 -> 60
B11: 7 | C11: 336 | D11: =SUM(C11-C10)*10 -> 30 | E11: =+D11+E10 -> 90
A12: 0 | B12: 8 | C12: 339 | D12: =SUM(C12-C11)*10 -> 30 | E12: =+D12+E11 -> 120
B13: 9 | C13: 342 | D13: =SUM(C13-C12)*10 -> 30 | E13: =+D13+E12 -> 150
B14: 10 | C14: 344 | D14: =SUM(C14-C13)*10 -> 20 | E14: =+D14+E13 -> 170
B15: 11 | C15: 346 | D15: =SUM(C15-C14)*10 -> 20 | E15: =+D15+E14 -> 190
A16: 0 | B16: 12 | C16: 348 | D16: =SUM(C16-C15)*10 -> 20 | E16: =+D16+E15 -> 210
B17: 13 | C17: 350 | D17: =SUM(C17-C16)*10 -> 20 | E17: =+D17+E16 -> 230
B18: 14 | C18: 352 | D18: =SUM(C18-C17)*10 -> 20 | E18: =+D18+E17 -> 250
B19: 15 | C19: 354 | D19: =SUM(C19-C18)*10 -> 20 | E19: =+D19+E18 -> 270
A20: 0 | B20: 16 | C20: 357 | D20: =SUM(C20-C19)*10 -> 30 | E20: =+D20+E19 -> 300
B21: 17 | C21: 360 | D21: =SUM(C21-C20)*10 -> 30 | E21: =+D21+E20 -> 330 | N21: 379
B22: 18 | C22: 363 | D22: =SUM(C22-C21)*10 -> 30 | E22: =+D22+E21 -> 360 | N22: ,,,,,,,,,,,,,,,,,,,,,,,,,,,,,,,,,,,,,,,,,,,,,,,,,,,,,,,,,,,,,,,,,,,,,,,,,,,,,,,,,,,,,,,,,,,,,,,,,,,,,,,,,,,,,,,,,,,,,,,,,,,,,,,,,,,,,,,,,,,,,,,,,,,,,,,,,,,,,,,,,,,,,,,,,,,,,,,,,,,,,,,,,,,,,,,,,,,,,,,,,,,,,,,,,,,,,,,,,,,,,,,,,,,,,,,,,,,,,,,,,,,,,,,,,,,,,,,,,,,,,,,,,,,,,,,,,,,,,,,,,,,,,,,,,,,,,,,,,,,,,,,,,,,,,,,,,,,,,,,,,,,,,,,,,,,,,,,,,,,,,,,,,,,,,,,,,,,,,,,,,,,,,,,,,,,,,,,,,,,,,,,,,,,,,,,,,,,,,,,,,,,,,,,,,,,,,,,,,,,,,,,,,,,,,,,,,,,,,,,,,,,,,,,,,,,,,,,,,,,,,,,,,,,,,,,,,,,,,,,,,,,,,,,,,,,,,,,,,,,,,,,,,,,,,,,,,,,,,,,,,,,,,,,,,,,,,,,,,,,,,,,,,,,,,,,,,,,,,,,,,,,,,,,,,,,,,,,,,,,,,,,,,,,,,,,,,,,,,,,,,,,,,,,,,,,,,,,,,,,,,,,,,,,,,,,,,,,,,,,,,,,,,,,,,,,,,,,,,,,,,,,,,,,,,,,,,,,,,,,,,,,,,,,,,,,,,,,,,,,,,,,,,,,,,,,,,,,,,,,,,,,,,,,,,,,,,,,,,,,,,,,,,,,,,,,,,,,,,,,,,,,,,,,,,,,,,,,,,,,,,,,,,,,,,,,,,,,,,,,,,,,,,,,,,,,,,,,,,,,,,,,,,,,,,,,,,,,,,,,,,,,,,,,,,,,,,,,,,,,,,,,,,,,,,,,,,,,,,,,,,,,,,,,,,,,,,,,,,,,,,,,,,,,,,,,,,,,,,,,,,,,,,,,,,,,,,,,,,,,,,,,,,,,,,,,,,,,,,,,,,,,,,,,,,,,,,,,,,,,,,,,,,,,,,,,,,,,,,,,,,,,,,,,,,,,,,,,,,,,,,,,,,,,,,,,,,,,,,,,,,,,,,,,,,,,,,,,,,,,,,,,,,,,,,,,,,,,,,,,,,,,,,,,,,,,,,,,,,,,,,,,,,,,,,,,,,,,,,,,,,,,,,,,,,,,,,,,,,,,,,,,,,,,,,,,,,,,,,,,,,,,,,,,,,,,,,,,,,,,,,,,,,,,,,,,,,,,,,,,,,,,,,,,,,,,,,,,,,,,,,,,,,,,,,,,,,,,,,,,,,,,,,,,,,,,,,,,,,,,,,,,,,,,,,,,,,,,,,,,,,,,,,,,,,,,,,,,,,,,,,,,,,,,,,,,,,,,,,,,,,,,,,,,,,,,,,,,,,,,,,,,,,,,,,,,,,,,,,,,,,,,,,,,,,,,,,,,,,,,,,,,,,,,,,,,,,,,,,,,,,,,,,,,,,,,,,,,,,,,,,,,,,,,,,,,,,,,,,,,,,,,,,,,,,,,,,,,,,,,,,,,,,,,,,,,,
B23: 19 | C23: 365 | D23: =SUM(C23-C22)*10 -> 20 | E23: =+D23+E22 -> 380
B24: 20 | C24: 367 | D24: =SUM(C24-C23)*10 -> 20 | E24: =+D24+E23 -> 400
B25: 21 | C25: 369 | D25: =SUM(C25-C24)*10 -> 20 | E25: =+D25+E24 -> 420
B26: 22 | C26: 370 | D26: =SUM(C26-C25)*10 -> 10 | E26: =+D26+E25 -> 430
B27: 23 | C27: 370 | D27: =SUM(C27-C26)*10 -> 0 | E27: =+D27+E26 -> 430
B28: 24 | C28: 370 | D28: =SUM(C28-C27)*10 -> 0 | E28: =+D28+E27 -> 430
B29: MAXIMO | C29: =MAX(C5:C28) -> 370 | D29: =MAX(D5:D28) -> 60 | E29: =MAX(E5:E28) -> 430
B30: MINIMO | C30: =MIN(C5:C28) -> 327 | D30: =MIN(D5:D28) -> 0 | E30: =MIN(E5:E28) -> 0
B31: PROMEDIO | C31: =AVERAGE(C5:C28) -> 348.75 | D31: =AVERAGE(D5:D28) -> 17.916667 | E31: =AVERAGE(E5:E28) -> 217.5
B32: TOTAL | C32: =SUM(C5:C28) -> 8370 | D32: =SUM(D5:D28) -> 430 | E32: =SUM(E5:E28) -> 5220

Sheet 6-MAYO-2026  
B1: REPORTE HORA A HORA MEDIDOR DE TANQUE ELEVADO
B3: DIA | C3: 46146
A4: 0 | B4: Hora | C4: LECTURA | D4: CONSOLIDADO (M3) | E4: consumo acumulado dia
B5: 1 | C5: 370 | D5: =C5-'5-MAYO-2026 '!C28 -> 0 | E5: =+D5 -> 0
B6: 2 | C6: 370 | D6: =SUM(C6-C5)*10 -> 0 | E6: =+D6+E5 -> 0
B7: 3 | C7: 370 | D7: =SUM(C7-C6)*10 -> 0 | E7: =+D7+E6 -> 0
B8: 4 | C8: 370 | D8: =SUM(C8-C7)*10 -> 0 | E8: =+D8+E7 -> 0
A9: 0 | B9: 5 | C9: 372 | D9: =SUM(C9-C8)*10 -> 20 | E9: =+D9+E8 -> 20
B10: 6 | C10: 376 | D10: =SUM(C10-C9)*10 -> 40 | E10: =+D10+E9 -> 60
B11: 7 | C11: 379 | D11: =SUM(C11-C10)*10 -> 30 | E11: =+D11+E10 -> 90
A12: 0 | B12: 8 | C12: 381 | D12: =SUM(C12-C11)*10 -> 20 | E12: =+D12+E11 -> 110
B13: 9 | C13: 384 | D13: =SUM(C13-C12)*10 -> 30 | E13: =+D13+E12 -> 140
B14: 10 | C14: 386 | D14: =SUM(C14-C13)*10 -> 20 | E14: =+D14+E13 -> 160
B15: 11 | C15: 388 | D15: =SUM(C15-C14)*10 -> 20 | E15: =+D15+E14 -> 180
A16: 0 | B16: 12 | C16: 391 | D16: =SUM(C16-C15)*10 -> 30 | E16: =+D16+E15 -> 210
B17: 13 | C17: 393 | D17: =SUM(C17-C16)*10 -> 20 | E17: =+D17+E16 -> 230
B18: 14 | C18: 395 | D18: =SUM(C18-C17)*10 -> 20 | E18: =+D18+E17 -> 250
B19: 15 | C19: 397 | D19: =SUM(C19-C18)*10 -> 20 | E19: =+D19+E18 -> 270
A20: 0 | B20: 16 | C20: 399 | D20: =SUM(C20-C19)*10 -> 20 | E20: =+D20+E19 -> 290
B21: 17 | C21: 401 | D21: =SUM(C21-C20)*10 -> 20 | E21: =+D21+E20 -> 310
B22: 18 | C22: 403 | D22: =SUM(C22-C21)*10 -> 20 | E22: =+D22+E21 -> 330
B23: 19 | C23: 405 | D23: =SUM(C23-C22)*10 -> 20 | E23: =+D23+E22 -> 350
B24: 20 | C24: 407 | D24: =SUM(C24-C23)*10 -> 20 | E24: =+D24+E23 -> 370
B25: 21 | C25: 410 | D25: =SUM(C25-C24)*10 -> 30 | E25: =+D25+E24 -> 400
B26: 22 | C26: 412 | D26: =SUM(C26-C25)*10 -> 20 | E26: =+D26+E25 -> 420
B27: 23 | C27: 412 | D27: =SUM(C27-C26)*10 -> 0 | E27: =+D27+E26 -> 420
B28: 24 | C28: 412 | D28: =SUM(C28-C27)*10 -> 0 | E28: =+D28+E27 -> 420
B29: MAXIMO | C29: =MAX(C5:C28) -> 412 | D29: =MAX(D5:D28) -> 40 | E29: =MAX(E5:E28) -> 420
B30: MINIMO | C30: =MIN(C5:C28) -> 370 | D30: =MIN(D5:D28) -> 0 | E30: =MIN(E5:E28) -> 0
B31: PROMEDIO | C31: =AVERAGE(C5:C28) -> 390.95833 | D31: =AVERAGE(D5:D28) -> 17.5 | E31: =AVERAGE(E5:E28) -> 209.58333
B32: TOTAL | C32: =SUM(C5:C28) -> 9383 | D32: =SUM(D5:D28) -> 420 | E32: =SUM(E5:E28) -> 5030

Sheet 7-MAYO-2026
B1: REPORTE HORA A HORA MEDIDOR DE TANQUE ELEVADO
B3: DIA | C3: 46146
A4: 0 | B4: Hora | C4: LECTURA | D4: CONSOLIDADO (M3) | E4: consumo acumulado dia
B5: 1 | C5: 412 | D5: =C5-'6-MAYO-2026 '!C28 -> 0 | E5: =+D5 -> 0
B6: 2 | C6: 412 | D6: =SUM(C6-C5)*10 -> 0 | E6: =+D6+E5 -> 0
B7: 3 | C7: 412 | D7: =SUM(C7-C6)*10 -> 0 | E7: =+D7+E6 -> 0
B8: 4 | C8: 412 | D8: =SUM(C8-C7)*10 -> 0 | E8: =+D8+E7 -> 0
A9: 0 | B9: 5 | C9: 415 | D9: =SUM(C9-C8)*10 -> 30 | E9: =+D9+E8 -> 30
B10: 6 | C10: 417 | D10: =SUM(C10-C9)*10 -> 20 | E10: =+D10+E9 -> 50
B11: 7 | C11: 419 | D11: =SUM(C11-C10)*10 -> 20 | E11: =+D11+E10 -> 70
A12: 0 | B12: 8 | C12: 422 | D12: =SUM(C12-C11)*10 -> 30 | E12: =+D12+E11 -> 100
B13: 9 | C13: 425 | D13: =SUM(C13-C12)*10 -> 30 | E13: =+D13+E12 -> 130
B14: 10 | C14: 428 | D14: =SUM(C14-C13)*10 -> 30 | E14: =+D14+E13 -> 160
B15: 11 | C15: 431 | D15: =SUM(C15-C14)*10 -> 30 | E15: =+D15+E14 -> 190
A16: 0 | B16: 12 | C16: 433 | D16: =SUM(C16-C15)*10 -> 20 | E16: =+D16+E15 -> 210
B17: 13 | C17: 435 | D17: =SUM(C17-C16)*10 -> 20 | E17: =+D17+E16 -> 230
B18: 14 | C18: 437 | D18: =SUM(C18-C17)*10 -> 20 | E18: =+D18+E17 -> 250
B19: 15 | C19: 439 | D19: =SUM(C19-C18)*10 -> 20 | E19: =+D19+E18 -> 270
A20: 0 | B20: 16 | C20: 440 | D20: =SUM(C20-C19)*10 -> 10 | E20: =+D20+E19 -> 280
B21: 17 | C21: 441 | D21: =SUM(C21-C20)*10 -> 10 | E21: =+D21+E20 -> 290
B22: 18 | C22: 443 | D22: =SUM(C22-C21)*10 -> 20 | E22: =+D22+E21 -> 310
B23: 19 | C23: 445 | D23: =SUM(C23-C22)*10 -> 20 | E23: =+D23+E22 -> 330
B24: 20 | C24: 447 | D24: =SUM(C24-C23)*10 -> 20 | E24: =+D24+E23 -> 350
B25: 21 | C25: 449 | D25: =SUM(C25-C24)*10 -> 20 | E25: =+D25+E24 -> 370
B26: 22 | C26: 451 | D26: =SUM(C26-C25)*10 -> 20 | E26: =+D26+E25 -> 390
B27: 23 | C27: 451 | D27: =SUM(C27-C26)*10 -> 0 | E27: =+D27+E26 -> 390
B28: 24 | C28: 451 | D28: =SUM(C28-C27)*10 -> 0 | E28: =+D28+E27 -> 390
B29: MAXIMO | C29: =MAX(C5:C28) -> 451 | D29: =MAX(D5:D28) -> 30 | E29: =MAX(E5:E28) -> 390
B30: MINIMO | C30: =MIN(C5:C28) -> 412 | D30: =MIN(D5:D28) -> 0 | E30: =MIN(E5:E28) -> 0
B31: PROMEDIO | C31: =AVERAGE(C5:C28) -> 431.95833 | D31: =AVERAGE(D5:D28) -> 16.25 | E31: =AVERAGE(E5:E28) -> 199.58333
B32: TOTAL | C32: =SUM(C5:C28) -> 10367 | D32: =SUM(D5:D28) -> 390 | E32: =SUM(E5:E28) -> 4790

Sheet 8-MAYO-2026
B1: REPORTE HORA A HORA MEDIDOR DE TANQUE ELEVADO
B3: DIA | C3: 46146
A4: 0 | B4: Hora | C4: LECTURA | D4: CONSOLIDADO (M3) | E4: consumo acumulado dia
B5: 1 | C5: 451 | D5: =C5-'7-MAYO-2026'!C28 -> 0 | E5: =+D5 -> 0
B6: 2 | C6: 451 | D6: =SUM(C6-C5)*10 -> 0 | E6: =+D6+E5 -> 0
B7: 3 | C7: 451 | D7: =SUM(C7-C6)*10 -> 0 | E7: =+D7+E6 -> 0
B8: 4 | C8: 451 | D8: =SUM(C8-C7)*10 -> 0 | E8: =+D8+E7 -> 0
A9: 0 | B9: 5 | C9: 453 | D9: =SUM(C9-C8)*10 -> 20 | E9: =+D9+E8 -> 20
B10: 6 | C10: 456 | D10: =SUM(C10-C9)*10 -> 30 | E10: =+D10+E9 -> 50
B11: 7 | C11: 459 | D11: =SUM(C11-C10)*10 -> 30 | E11: =+D11+E10 -> 80
A12: 0 | B12: 8 | C12: 462 | D12: =SUM(C12-C11)*10 -> 30 | E12: =+D12+E11 -> 110
B13: 9 | C13: 465 | D13: =SUM(C13-C12)*10 -> 30 | E13: =+D13+E12 -> 140
B14: 10 | C14: 468 | D14: =SUM(C14-C13)*10 -> 30 | E14: =+D14+E13 -> 170
B15: 11 | C15: 471 | D15: =SUM(C15-C14)*10 -> 30 | E15: =+D15+E14 -> 200
A16: 0 | B16: 12 | C16: 475 | D16: =SUM(C16-C15)*10 -> 40 | E16: =+D16+E15 -> 240
B17: 13 | C17: 477 | D17: =SUM(C17-C16)*10 -> 20 | E17: =+D17+E16 -> 260
B18: 14 | C18: 479 | D18: =SUM(C18-C17)*10 -> 20 | E18: =+D18+E17 -> 280
B19: 15 | C19: 481 | D19: =SUM(C19-C18)*10 -> 20 | E19: =+D19+E18 -> 300
A20: 0 | B20: 16 | C20: 483 | D20: =SUM(C20-C19)*10 -> 20 | E20: =+D20+E19 -> 320
B21: 17 | C21: 485 | D21: =SUM(C21-C20)*10 -> 20 | E21: =+D21+E20 -> 340
B22: 18 | C22: 487 | D22: =SUM(C22-C21)*10 -> 20 | E22: =+D22+E21 -> 360
B23: 19 | C23: 488 | D23: =SUM(C23-C22)*10 -> 10 | E23: =+D23+E22 -> 370
B24: 20 | C24: 490 | D24: =SUM(C24-C23)*10 -> 20 | E24: =+D24+E23 -> 390
B25: 21 | C25: 492 | D25: =SUM(C25-C24)*10 -> 20 | E25: =+D25+E24 -> 410
B26: 22 | C26: 495 | D26: =SUM(C26-C25)*10 -> 30 | E26: =+D26+E25 -> 440
B27: 23 | C27: 495 | D27: =SUM(C27-C26)*10 -> 0 | E27: =+D27+E26 -> 440
B28: 24 | C28: 495 | D28: =SUM(C28-C27)*10 -> 0 | E28: =+D28+E27 -> 440
B29: MAXIMO | C29: =MAX(C5:C28) -> 495 | D29: =MAX(D5:D28) -> 40 | E29: =MAX(E5:E28) -> 440
B30: MINIMO | C30: =MIN(C5:C28) -> 451 | D30: =MIN(D5:D28) -> 0 | E30: =MIN(E5:E28) -> 0
B31: PROMEDIO | C31: =AVERAGE(C5:C28) -> 473.33333 | D31: =AVERAGE(D5:D28) -> 18.333333 | E31: =AVERAGE(E5:E28) -> 223.33333
B32: TOTAL | C32: =SUM(C5:C28) -> 11360 | D32: =SUM(D5:D28) -> 440 | E32: =SUM(E5:E28) -> 5360

Sheet 9-MAYO-2026
B1: REPORTE HORA A HORA MEDIDOR DE TANQUE ELEVADO
B3: DIA | C3: 46146
A4: 0 | B4: Hora | C4: LECTURA | D4: CONSOLIDADO (M3) | E4: consumo acumulado dia
B5: 1 | C5: 495 | D5: =C5-'8-MAYO-2026'!C28 -> 0 | E5: =+D5 -> 0
B6: 2 | C6: 495 | D6: =SUM(C6-C5)*10 -> 0 | E6: =+D6+E5 -> 0
B7: 3 | C7: 495 | D7: =SUM(C7-C6)*10 -> 0 | E7: =+D7+E6 -> 0
B8: 4 | C8: 495 | D8: =SUM(C8-C7)*10 -> 0 | E8: =+D8+E7 -> 0
A9: 0 | B9: 5 | C9: 498 | D9: =SUM(C9-C8)*10 -> 30 | E9: =+D9+E8 -> 30
B10: 6 | C10: 501 | D10: =SUM(C10-C9)*10 -> 30 | E10: =+D10+E9 -> 60
B11: 7 | C11: 503 | D11: =SUM(C11-C10)*10 -> 20 | E11: =+D11+E10 -> 80
A12: 0 | B12: 8 | C12: 506 | D12: =SUM(C12-C11)*10 -> 30 | E12: =+D12+E11 -> 110
B13: 9 | C13: 509 | D13: =SUM(C13-C12)*10 -> 30 | E13: =+D13+E12 -> 140
B14: 10 | C14: 512 | D14: =SUM(C14-C13)*10 -> 30 | E14: =+D14+E13 -> 170
B15: 11 | C15: 516 | D15: =SUM(C15-C14)*10 -> 40 | E15: =+D15+E14 -> 210
A16: 0 | B16: 12 | C16: 519 | D16: =SUM(C16-C15)*10 -> 30 | E16: =+D16+E15 -> 240
B17: 13 | C17: 522 | D17: =SUM(C17-C16)*10 -> 30 | E17: =+D17+E16 -> 270
B18: 14 | C18: 525 | D18: =SUM(C18-C17)*10 -> 30 | E18: =+D18+E17 -> 300
B19: 15 | C19: 528 | D19: =SUM(C19-C18)*10 -> 30 | E19: =+D19+E18 -> 330
A20: 0 | B20: 16 | C20: 530 | D20: =SUM(C20-C19)*10 -> 20 | E20: =+D20+E19 -> 350
B21: 17 | C21: 532 | D21: =SUM(C21-C20)*10 -> 20 | E21: =+D21+E20 -> 370
B22: 18 | C22: 534 | D22: =SUM(C22-C21)*10 -> 20 | E22: =+D22+E21 -> 390
B23: 19 | C23: 537 | D23: =SUM(C23-C22)*10 -> 30 | E23: =+D23+E22 -> 420
B24: 20 | C24: 539 | D24: =SUM(C24-C23)*10 -> 20 | E24: =+D24+E23 -> 440
B25: 21 | C25: 542 | D25: =SUM(C25-C24)*10 -> 30 | E25: =+D25+E24 -> 470
B26: 22 | C26: 544 | D26: =SUM(C26-C25)*10 -> 20 | E26: =+D26+E25 -> 490
B27: 23 | C27: 544 | D27: =SUM(C27-C26)*10 -> 0 | E27: =+D27+E26 -> 490
B28: 24 | C28: 544 | D28: =SUM(C28-C27)*10 -> 0 | E28: =+D28+E27 -> 490
B29: MAXIMO | C29: =MAX(C5:C28) -> 544 | D29: =MAX(D5:D28) -> 40 | E29: =MAX(E5:E28) -> 490
B30: MINIMO | C30: =MIN(C5:C28) -> 495 | D30: =MIN(D5:D28) -> 0 | E30: =MIN(E5:E28) -> 0
B31: PROMEDIO | C31: =AVERAGE(C5:C28) -> 519.375 | D31: =AVERAGE(D5:D28) -> 20.416667 | E31: =AVERAGE(E5:E28) -> 243.75
B32: TOTAL | C32: =SUM(C5:C28) -> 12465 | D32: =SUM(D5:D28) -> 490 | E32: =SUM(E5:E28) -> 5850

Sheet 10-MAYO-2026 
B1: REPORTE HORA A HORA MEDIDOR DE TANQUE ELEVADO
B3: DIA | C3: 46146
A4: 0 | B4: Hora | C4: LECTURA | D4: CONSOLIDADO (M3) | E4: consumo acumulado dia
B5: 1 | C5: 544 | D5: =C5-'9-MAYO-2026'!C28 -> 0 | E5: =+D5 -> 0
B6: 2 | C6: 544 | D6: =SUM(C6-C5)*10 -> 0 | E6: =+D6+E5 -> 0
B7: 3 | C7: 544 | D7: =SUM(C7-C6)*10 -> 0 | E7: =+D7+E6 -> 0
B8: 4 | C8: 544 | D8: =SUM(C8-C7)*10 -> 0 | E8: =+D8+E7 -> 0
A9: 0 | B9: 5 | C9: 546 | D9: =SUM(C9-C8)*10 -> 20 | E9: =+D9+E8 -> 20
B10: 6 | C10: 549 | D10: =SUM(C10-C9)*10 -> 30 | E10: =+D10+E9 -> 50
B11: 7 | C11: 551 | D11: =SUM(C11-C10)*10 -> 20 | E11: =+D11+E10 -> 70
A12: 0 | B12: 8 | C12: 553 | D12: =SUM(C12-C11)*10 -> 20 | E12: =+D12+E11 -> 90
B13: 9 | C13: 556 | D13: =SUM(C13-C12)*10 -> 30 | E13: =+D13+E12 -> 120
B14: 10 | C14: 559 | D14: =SUM(C14-C13)*10 -> 30 | E14: =+D14+E13 -> 150
B15: 11 | C15: 563 | D15: =SUM(C15-C14)*10 -> 40 | E15: =+D15+E14 -> 190
A16: 0 | B16: 12 | C16: 567 | D16: =SUM(C16-C15)*10 -> 40 | E16: =+D16+E15 -> 230
B17: 13 | C17: 571 | D17: =SUM(C17-C16)*10 -> 40 | E17: =+D17+E16 -> 270
B18: 14 | C18: 574 | D18: =SUM(C18-C17)*10 -> 30 | E18: =+D18+E17 -> 300
B19: 15 | C19: 576 | D19: =SUM(C19-C18)*10 -> 20 | E19: =+D19+E18 -> 320
A20: 0 | B20: 16 | C20: 578 | D20: =SUM(C20-C19)*10 -> 20 | E20: =+D20+E19 -> 340
B21: 17 | C21: 580 | D21: =SUM(C21-C20)*10 -> 20 | E21: =+D21+E20 -> 360
B22: 18 | C22: 582 | D22: =SUM(C22-C21)*10 -> 20 | E22: =+D22+E21 -> 380
B23: 19 | C23: 586 | D23: =SUM(C23-C22)*10 -> 40 | E23: =+D23+E22 -> 420
B24: 20 | C24: 590 | D24: =SUM(C24-C23)*10 -> 40 | E24: =+D24+E23 -> 460
B25: 21 | C25: 594 | D25: =SUM(C25-C24)*10 -> 40 | E25: =+D25+E24 -> 500
B26: 22 | C26: 594 | D26: =SUM(C26-C25)*10 -> 0 | E26: =+D26+E25 -> 500
B27: 23 | C27: 594 | D27: =SUM(C27-C26)*10 -> 0 | E27: =+D27+E26 -> 500
B28: 24 | C28: 594 | D28: =SUM(C28-C27)*10 -> 0 | E28: =+D28+E27 -> 500
B29: MAXIMO | C29: =MAX(C5:C28) -> 594 | D29: =MAX(D5:D28) -> 40 | E29: =MAX(E5:E28) -> 500
B30: MINIMO | C30: =MIN(C5:C28) -> 544 | D30: =MIN(D5:D28) -> 0 | E30: =MIN(E5:E28) -> 0
B31: PROMEDIO | C31: =AVERAGE(C5:C28) -> 568.04167 | D31: =AVERAGE(D5:D28) -> 20.833333 | E31: =AVERAGE(E5:E28) -> 240.41667
B32: TOTAL | C32: =SUM(C5:C28) -> 13633 | D32: =SUM(D5:D28) -> 500 | E32: =SUM(E5:E28) -> 5770

Sheet 11-MAYO-2026  
B1: REPORTE HORA A HORA MEDIDOR DE TANQUE ELEVADO
B3: DIA | C3: 46153
A4: 0 | B4: Hora | C4: LECTURA | D4: CONSOLIDADO (M3) | E4: consumo acumulado dia
B5: 1 | C5: 594 | D5: =C5-'10-MAYO-2026 '!C28 -> 0 | E5: =+D5 -> 0
B6: 2 | C6: 594 | D6: =SUM(C6-C5)*10 -> 0 | E6: =+D6+E5 -> 0
B7: 3 | C7: 594 | D7: =SUM(C7-C6)*10 -> 0 | E7: =+D7+E6 -> 0
B8: 4 | C8: 594 | D8: =SUM(C8-C7)*10 -> 0 | E8: =+D8+E7 -> 0
A9: 0 | B9: 5 | C9: 596 | D9: =SUM(C9-C8)*10 -> 20 | E9: =+D9+E8 -> 20
B10: 6 | C10: 598 | D10: =SUM(C10-C9)*10 -> 20 | E10: =+D10+E9 -> 40
B11: 7 | C11: 600 | D11: =SUM(C11-C10)*10 -> 20 | E11: =+D11+E10 -> 60
A12: 0 | B12: 8 | C12: 602 | D12: =SUM(C12-C11)*10 -> 20 | E12: =+D12+E11 -> 80
B13: 9 | C13: 605 | D13: =SUM(C13-C12)*10 -> 30 | E13: =+D13+E12 -> 110
B14: 10 | C14: 608 | D14: =SUM(C14-C13)*10 -> 30 | E14: =+D14+E13 -> 140
B15: 11 | C15: 611 | D15: =SUM(C15-C14)*10 -> 30 | E15: =+D15+E14 -> 170
A16: 0 | B16: 12 | C16: 614 | D16: =SUM(C16-C15)*10 -> 30 | E16: =+D16+E15 -> 200
B17: 13 | C17: 616 | D17: =SUM(C17-C16)*10 -> 20 | E17: =+D17+E16 -> 220
B18: 14 | C18: 618 | D18: =SUM(C18-C17)*10 -> 20 | E18: =+D18+E17 -> 240
B19: 15 | C19: 620 | D19: =SUM(C19-C18)*10 -> 20 | E19: =+D19+E18 -> 260
A20: 0 | B20: 16 | C20: 621 | D20: =SUM(C20-C19)*10 -> 10 | E20: =+D20+E19 -> 270
B21: 17 | C21: 622 | D21: =SUM(C21-C20)*10 -> 10 | E21: =+D21+E20 -> 280
B22: 18 | C22: 624 | D22: =SUM(C22-C21)*10 -> 20 | E22: =+D22+E21 -> 300
B23: 19 | C23: 626 | D23: =SUM(C23-C22)*10 -> 20 | E23: =+D23+E22 -> 320
B24: 20 | C24: 628 | D24: =SUM(C24-C23)*10 -> 20 | E24: =+D24+E23 -> 340
B25: 21 | C25: 630 | D25: =SUM(C25-C24)*10 -> 20 | E25: =+D25+E24 -> 360
B26: 22 | C26: 633 | D26: =SUM(C26-C25)*10 -> 30 | E26: =+D26+E25 -> 390
B27: 23 | C27: 633 | D27: =SUM(C27-C26)*10 -> 0 | E27: =+D27+E26 -> 390
B28: 24 | C28: 633 | D28: =SUM(C28-C27)*10 -> 0 | E28: =+D28+E27 -> 390
B29: MAXIMO | C29: =MAX(C5:C28) -> 633 | D29: =MAX(D5:D28) -> 30 | E29: =MAX(E5:E28) -> 390
B30: MINIMO | C30: =MIN(C5:C28) -> 594 | D30: =MIN(D5:D28) -> 0 | E30: =MIN(E5:E28) -> 0
B31: PROMEDIO | C31: =AVERAGE(C5:C28) -> 613.08333 | D31: =AVERAGE(D5:D28) -> 16.25 | E31: =AVERAGE(E5:E28) -> 190.83333
B32: TOTAL | C32: =SUM(C5:C28) -> 14714 | D32: =SUM(D5:D28) -> 390 | E32: =SUM(E5:E28) -> 4580

Sheet 12-MAYO-2026  
B1: REPORTE HORA A HORA MEDIDOR DE TANQUE ELEVADO
B3: DIA | C3: 46153
A4: 0 | B4: Hora | C4: LECTURA | D4: CONSOLIDADO (M3) | E4: consumo acumulado dia
B5: 1 | C5: 633 | D5: =C5-'11-MAYO-2026 '!C28 -> 0 | E5: =+D5 -> 0
B6: 2 | C6: 633 | D6: =SUM(C6-C5)*10 -> 0 | E6: =+D6+E5 -> 0
B7: 3 | C7: 633 | D7: =SUM(C7-C6)*10 -> 0 | E7: =+D7+E6 -> 0
B8: 4 | C8: 633 | D8: =SUM(C8-C7)*10 -> 0 | E8: =+D8+E7 -> 0
A9: 0 | B9: 5 | C9: 636 | D9: =SUM(C9-C8)*10 -> 30 | E9: =+D9+E8 -> 30
B10: 6 | C10: 638 | D10: =SUM(C10-C9)*10 -> 20 | E10: =+D10+E9 -> 50
B11: 7 | C11: 640 | D11: =SUM(C11-C10)*10 -> 20 | E11: =+D11+E10 -> 70
A12: 0 | B12: 8 | C12: 643 | D12: =SUM(C12-C11)*10 -> 30 | E12: =+D12+E11 -> 100
B13: 9 | C13: 646 | D13: =SUM(C13-C12)*10 -> 30 | E13: =+D13+E12 -> 130
B14: 10 | C14: 648 | D14: =SUM(C14-C13)*10 -> 20 | E14: =+D14+E13 -> 150
B15: 11 | C15: 650 | D15: =SUM(C15-C14)*10 -> 20 | E15: =+D15+E14 -> 170
A16: 0 | B16: 12 | C16: 653 | D16: =SUM(C16-C15)*10 -> 30 | E16: =+D16+E15 -> 200
B17: 13 | C17: 656 | D17: =SUM(C17-C16)*10 -> 30 | E17: =+D17+E16 -> 230
B18: 14 | C18: 658 | D18: =SUM(C18-C17)*10 -> 20 | E18: =+D18+E17 -> 250
B19: 15 | C19: 660 | D19: =SUM(C19-C18)*10 -> 20 | E19: =+D19+E18 -> 270
A20: 0 | B20: 16 | C20: 661 | D20: =SUM(C20-C19)*10 -> 10 | E20: =+D20+E19 -> 280
B21: 17 | C21: 662 | D21: =SUM(C21-C20)*10 -> 10 | E21: =+D21+E20 -> 290
B22: 18 | C22: 665 | D22: =SUM(C22-C21)*10 -> 30 | E22: =+D22+E21 -> 320
B23: 19 | C23: 667 | D23: =SUM(C23-C22)*10 -> 20 | E23: =+D23+E22 -> 340
B24: 20 | C24: 669 | D24: =SUM(C24-C23)*10 -> 20 | E24: =+D24+E23 -> 360
B25: 21 | C25: 672 | D25: =SUM(C25-C24)*10 -> 30 | E25: =+D25+E24 -> 390
B26: 22 | C26: 675 | D26: =SUM(C26-C25)*10 -> 30 | E26: =+D26+E25 -> 420
B27: 23 | C27: 675 | D27: =SUM(C27-C26)*10 -> 0 | E27: =+D27+E26 -> 420
B28: 24 | C28: 675 | D28: =SUM(C28-C27)*10 -> 0 | E28: =+D28+E27 -> 420
B29: MAXIMO | C29: =MAX(C5:C28) -> 675 | D29: =MAX(D5:D28) -> 30 | E29: =MAX(E5:E28) -> 420
B30: MINIMO | C30: =MIN(C5:C28) -> 633 | D30: =MIN(D5:D28) -> 0 | E30: =MIN(E5:E28) -> 0
B31: PROMEDIO | C31: =AVERAGE(C5:C28) -> 653.375 | D31: =AVERAGE(D5:D28) -> 17.5 | E31: =AVERAGE(E5:E28) -> 203.75
B32: TOTAL | C32: =SUM(C5:C28) -> 15681 | D32: =SUM(D5:D28) -> 420 | E32: =SUM(E5:E28) -> 4890

Sheet 13-MAYO-2026  
B1: REPORTE HORA A HORA MEDIDOR DE TANQUE ELEVADO
B3: DIA | C3: 46153
A4: 0 | B4: Hora | C4: LECTURA | D4: CONSOLIDADO (M3) | E4: consumo acumulado dia
B5: 1 | C5: 675 | D5: =C5-'12-MAYO-2026 '!C28 -> 0 | E5: =+D5 -> 0
B6: 2 | C6: 675 | D6: =SUM(C6-C5)*10 -> 0 | E6: =+D6+E5 -> 0
B7: 3 | C7: 675 | D7: =SUM(C7-C6)*10 -> 0 | E7: =+D7+E6 -> 0
B8: 4 | C8: 675 | D8: =SUM(C8-C7)*10 -> 0 | E8: =+D8+E7 -> 0
A9: 0 | B9: 5 | C9: 678 | D9: =SUM(C9-C8)*10 -> 30 | E9: =+D9+E8 -> 30
B10: 6 | C10: 680 | D10: =SUM(C10-C9)*10 -> 20 | E10: =+D10+E9 -> 50
B11: 7 | C11: 682 | D11: =SUM(C11-C10)*10 -> 20 | E11: =+D11+E10 -> 70
A12: 0 | B12: 8 | C12: 684 | D12: =SUM(C12-C11)*10 -> 20 | E12: =+D12+E11 -> 90
B13: 9 | C13: 686 | D13: =SUM(C13-C12)*10 -> 20 | E13: =+D13+E12 -> 110
B14: 10 | C14: 689 | D14: =SUM(C14-C13)*10 -> 30 | E14: =+D14+E13 -> 140
B15: 11 | C15: 692 | D15: =SUM(C15-C14)*10 -> 30 | E15: =+D15+E14 -> 170
A16: 0 | B16: 12 | C16: 695 | D16: =SUM(C16-C15)*10 -> 30 | E16: =+D16+E15 -> 200
B17: 13 | C17: 698 | D17: =SUM(C17-C16)*10 -> 30 | E17: =+D17+E16 -> 230
B18: 14 | C18: 701 | D18: =SUM(C18-C17)*10 -> 30 | E18: =+D18+E17 -> 260
B19: 15 | C19: 703 | D19: =SUM(C19-C18)*10 -> 20 | E19: =+D19+E18 -> 280
A20: 0 | B20: 16 | C20: 705 | D20: =SUM(C20-C19)*10 -> 20 | E20: =+D20+E19 -> 300
B21: 17 | C21: 707 | D21: =SUM(C21-C20)*10 -> 20 | E21: =+D21+E20 -> 320
B22: 18 | C22: 709 | D22: =SUM(C22-C21)*10 -> 20 | E22: =+D22+E21 -> 340
B23: 19 | C23: 712 | D23: =SUM(C23-C22)*10 -> 30 | E23: =+D23+E22 -> 370
B24: 20 | C24: 714 | D24: =SUM(C24-C23)*10 -> 20 | E24: =+D24+E23 -> 390
B25: 21 | C25: 716 | D25: =SUM(C25-C24)*10 -> 20 | E25: =+D25+E24 -> 410
B26: 22 | C26: 719 | D26: =SUM(C26-C25)*10 -> 30 | E26: =+D26+E25 -> 440
B27: 23 | C27: 719 | D27: =SUM(C27-C26)*10 -> 0 | E27: =+D27+E26 -> 440
B28: 24 | C28: 719 | D28: =SUM(C28-C27)*10 -> 0 | E28: =+D28+E27 -> 440
B29: MAXIMO | C29: =MAX(C5:C28) -> 719 | D29: =MAX(D5:D28) -> 30 | E29: =MAX(E5:E28) -> 440
B30: MINIMO | C30: =MIN(C5:C28) -> 675 | D30: =MIN(D5:D28) -> 0 | E30: =MIN(E5:E28) -> 0
B31: PROMEDIO | C31: =AVERAGE(C5:C28) -> 696.16667 | D31: =AVERAGE(D5:D28) -> 18.333333 | E31: =AVERAGE(E5:E28) -> 211.66667
B32: TOTAL | C32: =SUM(C5:C28) -> 16708 | D32: =SUM(D5:D28) -> 440 | E32: =SUM(E5:E28) -> 5080

Sheet 14-MAYO-2026 
B1: REPORTE HORA A HORA MEDIDOR DE TANQUE ELEVADO
B3: DIA | C3: 46153
A4: 0 | B4: Hora | C4: LECTURA | D4: CONSOLIDADO (M3) | E4: consumo acumulado dia
B5: 1 | C5: 719 | D5: =C5-'13-MAYO-2026 '!C28 -> 0 | E5: =+D5 -> 0
B6: 2 | C6: 719 | D6: =SUM(C6-C5)*10 -> 0 | E6: =+D6+E5 -> 0
B7: 3 | C7: 719 | D7: =SUM(C7-C6)*10 -> 0 | E7: =+D7+E6 -> 0
B8: 4 | C8: 719 | D8: =SUM(C8-C7)*10 -> 0 | E8: =+D8+E7 -> 0
A9: 0 | B9: 5 | C9: 721 | D9: =SUM(C9-C8)*10 -> 20 | E9: =+D9+E8 -> 20
B10: 6 | C10: 723 | D10: =SUM(C10-C9)*10 -> 20 | E10: =+D10+E9 -> 40
B11: 7 | C11: 726 | D11: =SUM(C11-C10)*10 -> 30 | E11: =+D11+E10 -> 70
A12: 0 | B12: 8 | C12: 728 | D12: =SUM(C12-C11)*10 -> 20 | E12: =+D12+E11 -> 90
B13: 9 | C13: 730 | D13: =SUM(C13-C12)*10 -> 20 | E13: =+D13+E12 -> 110
B14: 10 | C14: 732 | D14: =SUM(C14-C13)*10 -> 20 | E14: =+D14+E13 -> 130
B15: 11 | C15: 734 | D15: =SUM(C15-C14)*10 -> 20 | E15: =+D15+E14 -> 150
A16: 0 | B16: 12 | C16: 736 | D16: =SUM(C16-C15)*10 -> 20 | E16: =+D16+E15 -> 170
B17: 13 | C17: 738 | D17: =SUM(C17-C16)*10 -> 20 | E17: =+D17+E16 -> 190
B18: 14 | C18: 740 | D18: =SUM(C18-C17)*10 -> 20 | E18: =+D18+E17 -> 210
B19: 15 | C19: 742 | D19: =SUM(C19-C18)*10 -> 20 | E19: =+D19+E18 -> 230
A20: 0 | B20: 16 | C20: 744 | D20: =SUM(C20-C19)*10 -> 20 | E20: =+D20+E19 -> 250
B21: 17 | C21: 746 | D21: =SUM(C21-C20)*10 -> 20 | E21: =+D21+E20 -> 270
B22: 18 | C22: 748 | D22: =SUM(C22-C21)*10 -> 20 | E22: =+D22+E21 -> 290
B23: 19 | C23: 753 | D23: =SUM(C23-C22)*10 -> 50 | E23: =+D23+E22 -> 340
B24: 20 | C24: 756 | D24: =SUM(C24-C23)*10 -> 30 | E24: =+D24+E23 -> 370
B25: 21 | C25: 759 | D25: =SUM(C25-C24)*10 -> 30 | E25: =+D25+E24 -> 400
B26: 22 | C26: 763 | D26: =SUM(C26-C25)*10 -> 40 | E26: =+D26+E25 -> 440
B27: 23 | C27: 763 | D27: =SUM(C27-C26)*10 -> 0 | E27: =+D27+E26 -> 440
B28: 24 | C28: 763 | D28: =SUM(C28-C27)*10 -> 0 | E28: =+D28+E27 -> 440
B29: MAXIMO | C29: =MAX(C5:C28) -> 763 | D29: =MAX(D5:D28) -> 50 | E29: =MAX(E5:E28) -> 440
B30: MINIMO | C30: =MIN(C5:C28) -> 719 | D30: =MIN(D5:D28) -> 0 | E30: =MIN(E5:E28) -> 0
B31: PROMEDIO | C31: =AVERAGE(C5:C28) -> 738.375 | D31: =AVERAGE(D5:D28) -> 18.333333 | E31: =AVERAGE(E5:E28) -> 193.75
B32: TOTAL | C32: =SUM(C5:C28) -> 17721 | D32: =SUM(D5:D28) -> 440 | E32: =SUM(E5:E28) -> 4650

Sheet 15-MAYO-2026  
B1: REPORTE HORA A HORA MEDIDOR DE TANQUE ELEVADO
B3: DIA | C3: 46153
A4: 0 | B4: Hora | C4: LECTURA | D4: CONSOLIDADO (M3) | E4: consumo acumulado dia
B5: 1 | C5: 763 | D5: =C5-'14-MAYO-2026 '!C28 -> 0 | E5: =+D5 -> 0
B6: 2 | C6: 763 | D6: =SUM(C6-C5)*10 -> 0 | E6: =+D6+E5 -> 0
B7: 3 | C7: 763 | D7: =SUM(C7-C6)*10 -> 0 | E7: =+D7+E6 -> 0
B8: 4 | C8: 763 | D8: =SUM(C8-C7)*10 -> 0 | E8: =+D8+E7 -> 0
A9: 0 | B9: 5 | C9: 765 | D9: =SUM(C9-C8)*10 -> 20 | E9: =+D9+E8 -> 20
B10: 6 | C10: 767 | D10: =SUM(C10-C9)*10 -> 20 | E10: =+D10+E9 -> 40
B11: 7 | C11: 768 | D11: =SUM(C11-C10)*10 -> 10 | E11: =+D11+E10 -> 50
A12: 0 | B12: 8 | C12: 770 | D12: =SUM(C12-C11)*10 -> 20 | E12: =+D12+E11 -> 70
B13: 9 | C13: 772 | D13: =SUM(C13-C12)*10 -> 20 | E13: =+D13+E12 -> 90
B14: 10 | C14: 775 | D14: =SUM(C14-C13)*10 -> 30 | E14: =+D14+E13 -> 120
B15: 11 | C15: 779 | D15: =SUM(C15-C14)*10 -> 40 | E15: =+D15+E14 -> 160
A16: 0 | B16: 12 | C16: 783 | D16: =SUM(C16-C15)*10 -> 40 | E16: =+D16+E15 -> 200
B17: 13 | C17: 785 | D17: =SUM(C17-C16)*10 -> 20 | E17: =+D17+E16 -> 220
B18: 14 | C18: 787 | D18: =SUM(C18-C17)*10 -> 20 | E18: =+D18+E17 -> 240
B19: 15 | C19: 791 | D19: =SUM(C19-C18)*10 -> 40 | E19: =+D19+E18 -> 280
A20: 0 | B20: 16 | C20: 794 | D20: =SUM(C20-C19)*10 -> 30 | E20: =+D20+E19 -> 310
B21: 17 | C21: 797 | D21: =SUM(C21-C20)*10 -> 30 | E21: =+D21+E20 -> 340
B22: 18 | C22: 800 | D22: =SUM(C22-C21)*10 -> 30 | E22: =+D22+E21 -> 370
B23: 19 | C23: 802 | D23: =SUM(C23-C22)*10 -> 20 | E23: =+D23+E22 -> 390
B24: 20 | C24: 804 | D24: =SUM(C24-C23)*10 -> 20 | E24: =+D24+E23 -> 410
B25: 21 | C25: 806 | D25: =SUM(C25-C24)*10 -> 20 | E25: =+D25+E24 -> 430
B26: 22 | C26: 808 | D26: =SUM(C26-C25)*10 -> 20 | E26: =+D26+E25 -> 450
B27: 23 | C27: 808 | D27: =SUM(C27-C26)*10 -> 0 | E27: =+D27+E26 -> 450
B28: 24 | C28: 808 | D28: =SUM(C28-C27)*10 -> 0 | E28: =+D28+E27 -> 450
B29: MAXIMO | C29: =MAX(C5:C28) -> 808 | D29: =MAX(D5:D28) -> 40 | E29: =MAX(E5:E28) -> 450
B30: MINIMO | C30: =MIN(C5:C28) -> 763 | D30: =MIN(D5:D28) -> 0 | E30: =MIN(E5:E28) -> 0
B31: PROMEDIO | C31: =AVERAGE(C5:C28) -> 784.20833 | D31: =AVERAGE(D5:D28) -> 18.75 | E31: =AVERAGE(E5:E28) -> 212.08333
B32: TOTAL | C32: =SUM(C5:C28) -> 18821 | D32: =SUM(D5:D28) -> 450 | E32: =SUM(E5:E28) -> 5090

Sheet 16-MAYO-2026 
B1: REPORTE HORA A HORA MEDIDOR DE TANQUE ELEVADO
B3: DIA | C3: 46158
A4: 0 | B4: Hora | C4: LECTURA | D4: CONSOLIDADO (M3) | E4: consumo acumulado dia
B5: 1 | C5: 808 | D5: =C5-808 -> 0 | E5: =+D5 -> 0
B6: 2 | C6: 808 | D6: =SUM(C6-C5)*10 -> 0 | E6: =+D6+E5 -> 0
B7: 3 | C7: 808 | D7: =SUM(C7-C6)*10 -> 0 | E7: =+D7+E6 -> 0
B8: 4 | C8: 808 | D8: =SUM(C8-C7)*10 -> 0 | E8: =+D8+E7 -> 0
A9: 0 | B9: 5 | C9: 810 | D9: =SUM(C9-C8)*10 -> 20 | E9: =+D9+E8 -> 20
B10: 6 | C10: 811 | D10: =SUM(C10-C9)*10 -> 10 | E10: =+D10+E9 -> 30
B11: 7 | C11: 813 | D11: =SUM(C11-C10)*10 -> 20 | E11: =+D11+E10 -> 50
A12: 0 | B12: 8 | C12: 815 | D12: =SUM(C12-C11)*10 -> 20 | E12: =+D12+E11 -> 70
B13: 9 | C13: 817 | D13: =SUM(C13-C12)*10 -> 20 | E13: =+D13+E12 -> 90
B14: 10 | C14: 820 | D14: =SUM(C14-C13)*10 -> 30 | E14: =+D14+E13 -> 120
B15: 11 | C15: 823 | D15: =SUM(C15-C14)*10 -> 30 | E15: =+D15+E14 -> 150
A16: 0 | B16: 12 | C16: 826 | D16: =SUM(C16-C15)*10 -> 30 | E16: =+D16+E15 -> 180
B17: 13 | C17: 828 | D17: =SUM(C17-C16)*10 -> 20 | E17: =+D17+E16 -> 200
B18: 14 | C18: 830 | D18: =SUM(C18-C17)*10 -> 20 | E18: =+D18+E17 -> 220
B19: 15 | C19: 832 | D19: =SUM(C19-C18)*10 -> 20 | E19: =+D19+E18 -> 240
A20: 0 | B20: 16 | C20: 834 | D20: =SUM(C20-C19)*10 -> 20 | E20: =+D20+E19 -> 260
B21: 17 | C21: 836 | D21: =SUM(C21-C20)*10 -> 20 | E21: =+D21+E20 -> 280
B22: 18 | C22: 839 | D22: =SUM(C22-C21)*10 -> 30 | E22: =+D22+E21 -> 310
B23: 19 | C23: 841 | D23: =SUM(C23-C22)*10 -> 20 | E23: =+D23+E22 -> 330
B24: 20 | C24: 843 | D24: =SUM(C24-C23)*10 -> 20 | E24: =+D24+E23 -> 350
B25: 21 | C25: 845 | D25: =SUM(C25-C24)*10 -> 20 | E25: =+D25+E24 -> 370
B26: 22 | C26: 847 | D26: =SUM(C26-C25)*10 -> 20 | E26: =+D26+E25 -> 390
B27: 23 | C27: 847 | D27: =SUM(C27-C26)*10 -> 0 | E27: =+D27+E26 -> 390
B28: 24 | C28: 847 | D28: =SUM(C28-C27)*10 -> 0 | E28: =+D28+E27 -> 390
B29: MAXIMO | C29: =MAX(C5:C28) -> 847 | D29: =MAX(D5:D28) -> 30 | E29: =MAX(E5:E28) -> 390
B30: MINIMO | C30: =MIN(C5:C28) -> 808 | D30: =MIN(D5:D28) -> 0 | E30: =MIN(E5:E28) -> 0
B31: PROMEDIO | C31: =AVERAGE(C5:C28) -> 826.5 | D31: =AVERAGE(D5:D28) -> 16.25 | E31: =AVERAGE(E5:E28) -> 185
B32: TOTAL | C32: =SUM(C5:C28) -> 19836 | D32: =SUM(D5:D28) -> 390 | E32: =SUM(E5:E28) -> 4440

Sheet 17-MAYO-2026
B1: REPORTE HORA A HORA MEDIDOR DE TANQUE ELEVADO
B3: DIA | C3: 46159
A4: 0 | B4: Hora | C4: LECTURA | D4: CONSOLIDADO (M3) | E4: consumo acumulado dia
B5: 1 | C5: 847 | D5: =C5-847 -> 0 | E5: =+D5 -> 0
B6: 2 | C6: 847 | D6: =SUM(C6-C5)*10 -> 0 | E6: =+D6+E5 -> 0
B7: 3 | C7: 847 | D7: =SUM(C7-C6)*10 -> 0 | E7: =+D7+E6 -> 0
B8: 4 | C8: 847 | D8: =SUM(C8-C7)*10 -> 0 | E8: =+D8+E7 -> 0
A9: 0 | B9: 5 | C9: 849 | D9: =SUM(C9-C8)*10 -> 20 | E9: =+D9+E8 -> 20
B10: 6 | C10: 851 | D10: =SUM(C10-C9)*10 -> 20 | E10: =+D10+E9 -> 40
B11: 7 | C11: 853 | D11: =SUM(C11-C10)*10 -> 20 | E11: =+D11+E10 -> 60
A12: 0 | B12: 8 | C12: 856 | D12: =SUM(C12-C11)*10 -> 30 | E12: =+D12+E11 -> 90
B13: 9 | C13: 859 | D13: =SUM(C13-C12)*10 -> 30 | E13: =+D13+E12 -> 120
B14: 10 | C14: 862 | D14: =SUM(C14-C13)*10 -> 30 | E14: =+D14+E13 -> 150
B15: 11 | C15: 865 | D15: =SUM(C15-C14)*10 -> 30 | E15: =+D15+E14 -> 180
A16: 0 | B16: 12 | C16: 869 | D16: =SUM(C16-C15)*10 -> 40 | E16: =+D16+E15 -> 220
B17: 13 | C17: 871 | D17: =SUM(C17-C16)*10 -> 20 | E17: =+D17+E16 -> 240
B18: 14 | C18: 873 | D18: =SUM(C18-C17)*10 -> 20 | E18: =+D18+E17 -> 260
B19: 15 | C19: 875 | D19: =SUM(C19-C18)*10 -> 20 | E19: =+D19+E18 -> 280
A20: 0 | B20: 16 | C20: 877 | D20: =SUM(C20-C19)*10 -> 20 | E20: =+D20+E19 -> 300
B21: 17 | C21: 879 | D21: =SUM(C21-C20)*10 -> 20 | E21: =+D21+E20 -> 320
B22: 18 | C22: 881 | D22: =SUM(C22-C21)*10 -> 20 | E22: =+D22+E21 -> 340
B23: 19 | C23: 884 | D23: =SUM(C23-C22)*10 -> 30 | E23: =+D23+E22 -> 370
B24: 20 | C24: 886 | D24: =SUM(C24-C23)*10 -> 20 | E24: =+D24+E23 -> 390
B25: 21 | C25: 888 | D25: =SUM(C25-C24)*10 -> 20 | E25: =+D25+E24 -> 410
B26: 22 | C26: 891 | D26: =SUM(C26-C25)*10 -> 30 | E26: =+D26+E25 -> 440
B27: 23 | C27: 891 | D27: =SUM(C27-C26)*10 -> 0 | E27: =+D27+E26 -> 440
B28: 24 | C28: 891 | D28: =SUM(C28-C27)*10 -> 0 | E28: =+D28+E27 -> 440
B29: MAXIMO | C29: =MAX(C5:C28) -> 891 | D29: =MAX(D5:D28) -> 40 | E29: =MAX(E5:E28) -> 440
B30: MINIMO | C30: =MIN(C5:C28) -> 847 | D30: =MIN(D5:D28) -> 0 | E30: =MIN(E5:E28) -> 0
B31: PROMEDIO | C31: =AVERAGE(C5:C28) -> 868.29167 | D31: =AVERAGE(D5:D28) -> 18.333333 | E31: =AVERAGE(E5:E28) -> 212.91667
B32: TOTAL | C32: =SUM(C5:C28) -> 20839 | D32: =SUM(D5:D28) -> 440 | E32: =SUM(E5:E28) -> 5110

Sheet 18-MAYO-2026 
B1: REPORTE HORA A HORA MEDIDOR DE TANQUE ELEVADO
B3: DIA | C3: 46159
A4: 0 | B4: Hora | C4: LECTURA | D4: CONSOLIDADO (M3) | E4: consumo acumulado dia
B5: 1 | C5: 891 | D5: 0 | E5: =+D5 -> 0
B6: 2 | C6: 891 | D6: =SUM(C6-C5)*10 -> 0 | E6: =+D6+E5 -> 0
B7: 3 | C7: 891 | D7: =SUM(C7-C6)*10 -> 0 | E7: =+D7+E6 -> 0
B8: 4 | C8: 891 | D8: =SUM(C8-C7)*10 -> 0 | E8: =+D8+E7 -> 0
A9: 0 | B9: 5 | C9: 893 | D9: =SUM(C9-C8)*10 -> 20 | E9: =+D9+E8 -> 20
B10: 6 | C10: 895 | D10: =SUM(C10-C9)*10 -> 20 | E10: =+D10+E9 -> 40
B11: 7 | C11: 897 | D11: =SUM(C11-C10)*10 -> 20 | E11: =+D11+E10 -> 60
A12: 0 | B12: 8 | C12: 900 | D12: =SUM(C12-C11)*10 -> 30 | E12: =+D12+E11 -> 90
B13: 9 | C13: 903 | D13: =SUM(C13-C12)*10 -> 30 | E13: =+D13+E12 -> 120
B14: 10 | C14: 906 | D14: =SUM(C14-C13)*10 -> 30 | E14: =+D14+E13 -> 150
B15: 11 | C15: 910 | D15: =SUM(C15-C14)*10 -> 40 | E15: =+D15+E14 -> 190
A16: 0 | B16: 12 | C16: 914 | D16: =SUM(C16-C15)*10 -> 40 | E16: =+D16+E15 -> 230
B17: 13 | C17: 917 | D17: =SUM(C17-C16)*10 -> 30 | E17: =+D17+E16 -> 260
B18: 14 | C18: 920 | D18: =SUM(C18-C17)*10 -> 30 | E18: =+D18+E17 -> 290
B19: 15 | C19: 923 | D19: =SUM(C19-C18)*10 -> 30 | E19: =+D19+E18 -> 320
A20: 0 | B20: 16 | C20: 925 | D20: =SUM(C20-C19)*10 -> 20 | E20: =+D20+E19 -> 340
B21: 17 | C21: 927 | D21: =SUM(C21-C20)*10 -> 20 | E21: =+D21+E20 -> 360
B22: 18 | C22: 929 | D22: =SUM(C22-C21)*10 -> 20 | E22: =+D22+E21 -> 380
B23: 19 | C23: 932 | D23: =SUM(C23-C22)*10 -> 30 | E23: =+D23+E22 -> 410
B24: 20 | C24: 934 | D24: =SUM(C24-C23)*10 -> 20 | E24: =+D24+E23 -> 430
B25: 21 | C25: 936 | D25: =SUM(C25-C24)*10 -> 20 | E25: =+D25+E24 -> 450
B26: 22 | C26: 938 | D26: =SUM(C26-C25)*10 -> 20 | E26: =+D26+E25 -> 470
B27: 23 | C27: 938 | D27: =SUM(C27-C26)*10 -> 0 | E27: =+D27+E26 -> 470
B28: 24 | C28: 938 | D28: =SUM(C28-C27)*10 -> 0 | E28: =+D28+E27 -> 470
B29: MAXIMO | C29: =MAX(C5:C28) -> 938 | D29: =MAX(D5:D28) -> 40 | E29: =MAX(E5:E28) -> 470
B30: MINIMO | C30: =MIN(C5:C28) -> 891 | D30: =MIN(D5:D28) -> 0 | E30: =MIN(E5:E28) -> 0
B31: PROMEDIO | C31: =AVERAGE(C5:C28) -> 914.125 | D31: =AVERAGE(D5:D28) -> 19.583333 | E31: =AVERAGE(E5:E28) -> 231.25
B32: TOTAL | C32: =SUM(C5:C28) -> 21939 | D32: =SUM(D5:D28) -> 470 | E32: =SUM(E5:E28) -> 5550

Sheet 19-MAYO-2026  
B1: REPORTE HORA A HORA MEDIDOR DE TANQUE ELEVADO
B3: DIA | C3: 46159
A4: 0 | B4: Hora | C4: LECTURA | D4: CONSOLIDADO (M3) | E4: consumo acumulado dia
B5: 1 | C5: 938 | D5: =C5-938 -> 0 | E5: =+D5 -> 0
B6: 2 | C6: 938 | D6: =SUM(C6-C5)*10 -> 0 | E6: =+D6+E5 -> 0
B7: 3 | C7: 938 | D7: =SUM(C7-C6)*10 -> 0 | E7: =+D7+E6 -> 0
B8: 4 | C8: 938 | D8: =SUM(C8-C7)*10 -> 0 | E8: =+D8+E7 -> 0
A9: 0 | B9: 5 | C9: 940 | D9: =SUM(C9-C8)*10 -> 20 | E9: =+D9+E8 -> 20
B10: 6 | C10: 943 | D10: =SUM(C10-C9)*10 -> 30 | E10: =+D10+E9 -> 50
B11: 7 | C11: 947 | D11: =SUM(C11-C10)*10 -> 40 | E11: =+D11+E10 -> 90
A12: 0 | B12: 8 | C12: 949 | D12: =SUM(C12-C11)*10 -> 20 | E12: =+D12+E11 -> 110
B13: 9 | C13: 951 | D13: =SUM(C13-C12)*10 -> 20 | E13: =+D13+E12 -> 130
B14: 10 | C14: 953 | D14: =SUM(C14-C13)*10 -> 20 | E14: =+D14+E13 -> 150
B15: 11 | C15: 955 | D15: =SUM(C15-C14)*10 -> 20 | E15: =+D15+E14 -> 170
A16: 0 | B16: 12 | C16: 956 | D16: =SUM(C16-C15)*10 -> 10 | E16: =+D16+E15 -> 180
B17: 13 | C17: 958 | D17: =SUM(C17-C16)*10 -> 20 | E17: =+D17+E16 -> 200
B18: 14 | C18: 960 | D18: =SUM(C18-C17)*10 -> 20 | E18: =+D18+E17 -> 220
B19: 15 | C19: 962 | D19: =SUM(C19-C18)*10 -> 20 | E19: =+D19+E18 -> 240
A20: 0 | B20: 16 | C20: 964 | D20: =SUM(C20-C19)*10 -> 20 | E20: =+D20+E19 -> 260
B21: 17 | C21: 966 | D21: =SUM(C21-C20)*10 -> 20 | E21: =+D21+E20 -> 280
B22: 18 | C22: 968 | D22: =SUM(C22-C21)*10 -> 20 | E22: =+D22+E21 -> 300
B23: 19 | C23: 970 | D23: =SUM(C23-C22)*10 -> 20 | E23: =+D23+E22 -> 320
B24: 20 | C24: 972 | D24: =SUM(C24-C23)*10 -> 20 | E24: =+D24+E23 -> 340
B25: 21 | C25: 974 | D25: =SUM(C25-C24)*10 -> 20 | E25: =+D25+E24 -> 360
B26: 22 | C26: 978 | D26: =SUM(C26-C25)*10 -> 40 | E26: =+D26+E25 -> 400
B27: 23 | C27: 978 | D27: =SUM(C27-C26)*10 -> 0 | E27: =+D27+E26 -> 400
B28: 24 | C28: 978 | D28: =SUM(C28-C27)*10 -> 0 | E28: =+D28+E27 -> 400
B29: MAXIMO | C29: =MAX(C5:C28) -> 978 | D29: =MAX(D5:D28) -> 40 | E29: =MAX(E5:E28) -> 400
B30: MINIMO | C30: =MIN(C5:C28) -> 938 | D30: =MIN(D5:D28) -> 0 | E30: =MIN(E5:E28) -> 0
B31: PROMEDIO | C31: =AVERAGE(C5:C28) -> 957.25 | D31: =AVERAGE(D5:D28) -> 16.666667 | E31: =AVERAGE(E5:E28) -> 192.5
B32: TOTAL | C32: =SUM(C5:C28) -> 22974 | D32: =SUM(D5:D28) -> 400 | E32: =SUM(E5:E28) -> 4620

Sheet 20-MAYO-2026
B1: REPORTE HORA A HORA MEDIDOR DE TANQUE ELEVADO
B3: DIA | C3: 46159
A4: 0 | B4: Hora | C4: LECTURA | D4: CONSOLIDADO (M3) | E4: consumo acumulado dia
B5: 1 | C5: 978 | D5: =C5-978 -> 0 | E5: =+D5 -> 0
B6: 2 | C6: 978 | D6: =SUM(C6-C5)*10 -> 0 | E6: =+D6+E5 -> 0
B7: 3 | C7: 978 | D7: =SUM(C7-C6)*10 -> 0 | E7: =+D7+E6 -> 0
B8: 4 | C8: 978 | D8: =SUM(C8-C7)*10 -> 0 | E8: =+D8+E7 -> 0
A9: 0 | B9: 5 | C9: 980 | D9: =SUM(C9-C8)*10 -> 20 | E9: =+D9+E8 -> 20
B10: 6 | C10: 982 | D10: =SUM(C10-C9)*10 -> 20 | E10: =+D10+E9 -> 40
B11: 7 | C11: 987 | D11: =SUM(C11-C10)*10 -> 50 | E11: =+D11+E10 -> 90
A12: 0 | B12: 8 | C12: 989 | D12: =SUM(C12-C11)*10 -> 20 | E12: =+D12+E11 -> 110
B13: 9 | C13: 992 | D13: =SUM(C13-C12)*10 -> 30 | E13: =+D13+E12 -> 140
B14: 10 | C14: 995 | D14: =SUM(C14-C13)*10 -> 30 | E14: =+D14+E13 -> 170
B15: 11 | C15: 997 | D15: =SUM(C15-C14)*10 -> 20 | E15: =+D15+E14 -> 190
A16: 0 | B16: 12 | C16: 999 | D16: =SUM(C16-C15)*10 -> 20 | E16: =+D16+E15 -> 210
B17: 13 | C17: 1001 | D17: =SUM(C17-C16)*10 -> 20 | E17: =+D17+E16 -> 230
B18: 14 | C18: 1003 | D18: =SUM(C18-C17)*10 -> 20 | E18: =+D18+E17 -> 250
B19: 15 | C19: 1005 | D19: =SUM(C19-C18)*10 -> 20 | E19: =+D19+E18 -> 270
A20: 0 | B20: 16 | C20: 1007 | D20: =SUM(C20-C19)*10 -> 20 | E20: =+D20+E19 -> 290
B21: 17 | C21: 1009 | D21: =SUM(C21-C20)*10 -> 20 | E21: =+D21+E20 -> 310
B22: 18 | C22: 1011 | D22: =SUM(C22-C21)*10 -> 20 | E22: =+D22+E21 -> 330
B23: 19 | C23: 1013 | D23: =SUM(C23-C22)*10 -> 20 | E23: =+D23+E22 -> 350
B24: 20 | C24: 1015 | D24: =SUM(C24-C23)*10 -> 20 | E24: =+D24+E23 -> 370
B25: 21 | C25: 1017 | D25: =SUM(C25-C24)*10 -> 20 | E25: =+D25+E24 -> 390
B26: 22 | C26: 1019 | D26: =SUM(C26-C25)*10 -> 20 | E26: =+D26+E25 -> 410
B27: 23 | D27: 0 | E27: =+D27+E26 -> 410
B28: 24 | D28: =SUM(C28-C27)*10 -> 0 | E28: =+D28+E27 -> 410
B29: MAXIMO | C29: =MAX(C5:C28) -> 1019 | D29: =MAX(D5:D28) -> 50 | E29: =MAX(E5:E28) -> 410
B30: MINIMO | C30: =MIN(C5:C28) -> 978 | D30: =MIN(D5:D28) -> 0 | E30: =MIN(E5:E28) -> 0
B31: PROMEDIO | C31: =AVERAGE(C5:C28) -> 996.95455 | D31: =AVERAGE(D5:D28) -> 17.083333 | E31: =AVERAGE(E5:E28) -> 207.91667
B32: TOTAL | C32: =SUM(C5:C28) -> 21933 | D32: =SUM(D5:D28) -> 410 | E32: =SUM(E5:E28) -> 4990

Sheet 21-MAYO-2026 
B1: REPORTE HORA A HORA MEDIDOR DE TANQUE ELEVADO
B3: DIA | C3: 46159
A4: 0 | B4: Hora | C4: LECTURA | D4: CONSOLIDADO (M3) | E4: consumo acumulado dia
B5: 1 | C5: 1019 | D5: 0 | E5: =+D5 -> 0
B6: 2 | C6: 1019 | D6: =SUM(C6-C5)*10 -> 0 | E6: =+D6+E5 -> 0
B7: 3 | C7: 1019 | D7: =SUM(C7-C6)*10 -> 0 | E7: =+D7+E6 -> 0
B8: 4 | C8: 1019 | D8: =SUM(C8-C7)*10 -> 0 | E8: =+D8+E7 -> 0
A9: 0 | B9: 5 | C9: 1021 | D9: =SUM(C9-C8)*10 -> 20 | E9: =+D9+E8 -> 20
B10: 6 | C10: 1023 | D10: =SUM(C10-C9)*10 -> 20 | E10: =+D10+E9 -> 40
B11: 7 | C11: 1025 | D11: =SUM(C11-C10)*10 -> 20 | E11: =+D11+E10 -> 60
A12: 0 | B12: 8 | C12: 1028 | D12: =SUM(C12-C11)*10 -> 30 | E12: =+D12+E11 -> 90
B13: 9 | C13: 1030 | D13: =SUM(C13-C12)*10 -> 20 | E13: =+D13+E12 -> 110
B14: 10 | C14: 1032 | D14: =SUM(C14-C13)*10 -> 20 | E14: =+D14+E13 -> 130
B15: 11 | C15: 1034 | D15: =SUM(C15-C14)*10 -> 20 | E15: =+D15+E14 -> 150
A16: 0 | B16: 12 | C16: 1036 | D16: =SUM(C16-C15)*10 -> 20 | E16: =+D16+E15 -> 170
B17: 13 | C17: 1038 | D17: =SUM(C17-C16)*10 -> 20 | E17: =+D17+E16 -> 190
B18: 14 | C18: 1040 | D18: =SUM(C18-C17)*10 -> 20 | E18: =+D18+E17 -> 210
B19: 15 | C19: 1042 | D19: =SUM(C19-C18)*10 -> 20 | E19: =+D19+E18 -> 230
A20: 0 | B20: 16 | C20: 1044 | D20: =SUM(C20-C19)*10 -> 20 | E20: =+D20+E19 -> 250
B21: 17 | C21: 1046 | D21: =SUM(C21-C20)*10 -> 20 | E21: =+D21+E20 -> 270
B22: 18 | C22: 1048 | D22: =SUM(C22-C21)*10 -> 20 | E22: =+D22+E21 -> 290
B23: 19 | C23: 1050 | D23: =SUM(C23-C22)*10 -> 20 | E23: =+D23+E22 -> 310
B24: 20 | C24: 1052 | D24: =SUM(C24-C23)*10 -> 20 | E24: =+D24+E23 -> 330
B25: 21 | C25: 1054 | D25: =SUM(C25-C24)*10 -> 20 | E25: =+D25+E24 -> 350
B26: 22 | C26: 1056 | D26: =SUM(C26-C25)*10 -> 20 | E26: =+D26+E25 -> 370
B27: 23 | C27: 1056 | D27: =SUM(C27-C26)*10 -> 0 | E27: =+D27+E26 -> 370
B28: 24 | C28: 1056 | D28: =SUM(C28-C27)*10 -> 0 | E28: =+D28+E27 -> 370
B29: MAXIMO | C29: =MAX(C5:C28) -> 1056 | D29: =MAX(D5:D28) -> 30 | E29: =MAX(E5:E28) -> 370
B30: MINIMO | C30: =MIN(C5:C28) -> 1019 | D30: =MIN(D5:D28) -> 0 | E30: =MIN(E5:E28) -> 0
B31: PROMEDIO | C31: =AVERAGE(C5:C28) -> 1036.9583 | D31: =AVERAGE(D5:D28) -> 15.416667 | E31: =AVERAGE(E5:E28) -> 179.58333
B32: TOTAL | C32: =SUM(C5:C28) -> 24887 | D32: =SUM(D5:D28) -> 370 | E32: =SUM(E5:E28) -> 4310

Sheet 22-MAYO-2026  
B1: REPORTE HORA A HORA MEDIDOR DE TANQUE ELEVADO
B3: DIA | C3: 46159
A4: 0 | B4: Hora | C4: LECTURA | D4: CONSOLIDADO (M3) | E4: consumo acumulado dia
B5: 1 | C5: 1056 | D5: 0 | E5: =+D5 -> 0
B6: 2 | C6: 1056 | D6: =SUM(C6-C5)*10 -> 0 | E6: =+D6+E5 -> 0
B7: 3 | C7: 1056 | D7: =SUM(C7-C6)*10 -> 0 | E7: =+D7+E6 -> 0
B8: 4 | C8: 1056 | D8: =SUM(C8-C7)*10 -> 0 | E8: =+D8+E7 -> 0
A9: 0 | B9: 5 | C9: 1059 | D9: =SUM(C9-C8)*10 -> 30 | E9: =+D9+E8 -> 30
B10: 6 | C10: 1062 | D10: =SUM(C10-C9)*10 -> 30 | E10: =+D10+E9 -> 60
B11: 7 | C11: 1065 | D11: =SUM(C11-C10)*10 -> 30 | E11: =+D11+E10 -> 90
A12: 0 | B12: 8 | C12: 1068 | D12: =SUM(C12-C11)*10 -> 30 | E12: =+D12+E11 -> 120
B13: 9 | C13: 1071 | D13: =SUM(C13-C12)*10 -> 30 | E13: =+D13+E12 -> 150
B14: 10 | C14: 1074 | D14: =SUM(C14-C13)*10 -> 30 | E14: =+D14+E13 -> 180
B15: 11 | C15: 1077 | D15: =SUM(C15-C14)*10 -> 30 | E15: =+D15+E14 -> 210
A16: 0 | B16: 12 | C16: 1080 | D16: =SUM(C16-C15)*10 -> 30 | E16: =+D16+E15 -> 240
B17: 13 | C17: 1083 | D17: =SUM(C17-C16)*10 -> 30 | E17: =+D17+E16 -> 270
B18: 14 | C18: 1086 | D18: =SUM(C18-C17)*10 -> 30 | E18: =+D18+E17 -> 300
B19: 15 | C19: 1089 | D19: =SUM(C19-C18)*10 -> 30 | E19: =+D19+E18 -> 330
A20: 0 | B20: 16 | C20: 1092 | D20: =SUM(C20-C19)*10 -> 30 | E20: =+D20+E19 -> 360
B21: 17 | C21: 1095 | D21: =SUM(C21-C20)*10 -> 30 | E21: =+D21+E20 -> 390
B22: 18 | C22: 1098 | D22: =SUM(C22-C21)*10 -> 30 | E22: =+D22+E21 -> 420
